Workbook

Sheet CFP
B2: OWL | K2: =B2 -> OWL | T2: =B2 -> OWL
B4: BALANCE | C4: =BALANCES!B1 -> 46073 | K4: FLOWS | L4: =C4 -> 46073 | M4: <---> | N4: =U4 -> 46081 | T4: BALANCE | U4: 46081
B6: BANK | C6: USD | D6: EUR | E6: CNY | F6: AED | G6: RUB | H6: OMR | I6: TOTAL USD | K6: BANK | L6: =C6 -> USD | M6: =D6 -> EUR | N6: =E6 -> CNY | O6: =F6 -> AED | P6: =G6 -> RUB | Q6: =H6 -> OMR | R6: TOTAL USD | T6: BANK | U6: =C6 -> USD | V6: =D6 -> EUR | W6: =E6 -> CNY | X6: =F6 -> AED | Y6: =G6 -> RUB | Z6: =H6 -> OMR | AA6: TOTAL USD | AC6: CHECK
B7: EMLAK | C7: {=SUMIFS(BALANCES!$C:$C,BALANCES!$A:$A,$B$2,BALANCES!$B:$B,$B7,BALANCES!$D:$D,C$6)+SUMIFS(FLOWS!$C:$C,FLOWS!$A:$A,$B$2,FLOWS!$E:$E,$B7,FLOWS!$D:$D,C$6,FLOWS!$H:$H,"<"&$C$4)+SUM(SUMIFS(DEALS!$J:$J,DEALS!$A:$A,{"*REFUND*","*EXECUTED*"},DEALS!$G:$G,$B$2,DEALS!$E:$E,"<"&$C$4,DEALS!$K:$K,C$6,DEALS!$M:$M,$B7,DEALS!$N:$N,"<>*RECEIVED*",DEALS!$N:$N,"<>*EXECUTED*"))+SUM(SUMIFS(DEALS!$R:$R,DEALS!$A:$A,{"*REFUND*","*EXECUTED*"},DEALS!$O:$O,$B$2,DEALS!$E:$E,"<"&$C$4,DEALS!$S:$S,C$6,DEALS!$U:$U,$B7,DEALS!$V:$V,"<>*RECEIVED*",DEALS!$V:$V,"<>*EXECUTED*"))} -> 2197.03 | D7: {=SUMIFS(BALANCES!$C:$C,BALANCES!$A:$A,$B$2,BALANCES!$B:$B,$B7,BALANCES!$D:$D,D$6)+SUMIFS(FLOWS!$C:$C,FLOWS!$A:$A,$B$2,FLOWS!$E:$E,$B7,FLOWS!$D:$D,D$6,FLOWS!$H:$H,"<"&$C$4)+SUM(SUMIFS(DEALS!$J:$J,DEALS!$A:$A,{"*REFUND*","*EXECUTED*"},DEALS!$G:$G,$B$2,DEALS!$E:$E,"<"&$C$4,DEALS!$K:$K,D$6,DEALS!$M:$M,$B7,DEALS!$N:$N,"<>*RECEIVED*",DEALS!$N:$N,"<>*EXECUTED*"))+SUM(SUMIFS(DEALS!$R:$R,DEALS!$A:$A,{"*REFUND*","*EXECUTED*"},DEALS!$O:$O,$B$2,DEALS!$E:$E,"<"&$C$4,DEALS!$S:$S,D$6,DEALS!$U:$U,$B7,DEALS!$V:$V,"<>*RECEIVED*",DEALS!$V:$V,"<>*EXECUTED*"))} -> 44.88 | E7: {=SUMIFS(BALANCES!$C:$C,BALANCES!$A:$A,$B$2,BALANCES!$B:$B,$B7,BALANCES!$D:$D,E$6)+SUMIFS(FLOWS!$C:$C,FLOWS!$A:$A,$B$2,FLOWS!$E:$E,$B7,FLOWS!$D:$D,E$6,FLOWS!$H:$H,"<"&$C$4)+SUM(SUMIFS(DEALS!$J:$J,DEALS!$A:$A,{"*REFUND*","*EXECUTED*"},DEALS!$G:$G,$B$2,DEALS!$E:$E,"<"&$C$4,DEALS!$K:$K,E$6,DEALS!$M:$M,$B7,DEALS!$N:$N,"<>*RECEIVED*",DEALS!$N:$N,"<>*EXECUTED*"))+SUM(SUMIFS(DEALS!$R:$R,DEALS!$A:$A,{"*REFUND*","*EXECUTED*"},DEALS!$O:$O,$B$2,DEALS!$E:$E,"<"&$C$4,DEALS!$S:$S,E$6,DEALS!$U:$U,$B7,DEALS!$V:$V,"<>*RECEIVED*",DEALS!$V:$V,"<>*EXECUTED*"))} -> 54.77 | F7: {=SUMIFS(BALANCES!$C:$C,BALANCES!$A:$A,$B$2,BALANCES!$B:$B,$B7,BALANCES!$D:$D,F$6)+SUMIFS(FLOWS!$C:$C,FLOWS!$A:$A,$B$2,FLOWS!$E:$E,$B7,FLOWS!$D:$D,F$6,FLOWS!$H:$H,"<"&$C$4)+SUM(SUMIFS(DEALS!$J:$J,DEALS!$A:$A,{"*REFUND*","*EXECUTED*"},DEALS!$G:$G,$B$2,DEALS!$E:$E,"<"&$C$4,DEALS!$K:$K,F$6,DEALS!$M:$M,$B7,DEALS!$N:$N,"<>*RECEIVED*",DEALS!$N:$N,"<>*EXECUTED*"))+SUM(SUMIFS(DEALS!$R:$R,DEALS!$A:$A,{"*REFUND*","*EXECUTED*"},DEALS!$O:$O,$B$2,DEALS!$E:$E,"<"&$C$4,DEALS!$S:$S,F$6,DEALS!$U:$U,$B7,DEALS!$V:$V,"<>*RECEIVED*",DEALS!$V:$V,"<>*EXECUTED*"))} -> 6221.49 | G7: {=SUMIFS(BALANCES!$C:$C,BALANCES!$A:$A,$B$2,BALANCES!$B:$B,$B7,BALANCES!$D:$D,G$6)+SUMIFS(FLOWS!$C:$C,FLOWS!$A:$A,$B$2,FLOWS!$E:$E,$B7,FLOWS!$D:$D,G$6,FLOWS!$H:$H,"<"&$C$4)+SUM(SUMIFS(DEALS!$J:$J,DEALS!$A:$A,{"*REFUND*","*EXECUTED*"},DEALS!$G:$G,$B$2,DEALS!$E:$E,"<"&$C$4,DEALS!$K:$K,G$6,DEALS!$M:$M,$B7,DEALS!$N:$N,"<>*RECEIVED*",DEALS!$N:$N,"<>*EXECUTED*"))+SUM(SUMIFS(DEALS!$R:$R,DEALS!$A:$A,{"*REFUND*","*EXECUTED*"},DEALS!$O:$O,$B$2,DEALS!$E:$E,"<"&$C$4,DEALS!$S:$S,G$6,DEALS!$U:$U,$B7,DEALS!$V:$V,"<>*RECEIVED*",DEALS!$V:$V,"<>*EXECUTED*"))} -> 0 | H7: {=SUMIFS(BALANCES!$C:$C,BALANCES!$A:$A,$B$2,BALANCES!$B:$B,$B7,BALANCES!$D:$D,H$6)+SUMIFS(FLOWS!$C:$C,FLOWS!$A:$A,$B$2,FLOWS!$E:$E,$B7,FLOWS!$D:$D,H$6,FLOWS!$H:$H,"<"&$C$4)+SUM(SUMIFS(DEALS!$J:$J,DEALS!$A:$A,{"*REFUND*","*EXECUTED*"},DEALS!$G:$G,$B$2,DEALS!$E:$E,"<"&$C$4,DEALS!$K:$K,H$6,DEALS!$M:$M,$B7,DEALS!$N:$N,"<>*RECEIVED*",DEALS!$N:$N,"<>*EXECUTED*"))+SUM(SUMIFS(DEALS!$R:$R,DEALS!$A:$A,{"*REFUND*","*EXECUTED*"},DEALS!$O:$O,$B$2,DEALS!$E:$E,"<"&$C$4,DEALS!$S:$S,H$6,DEALS!$U:$U,$B7,DEALS!$V:$V,"<>*RECEIVED*",DEALS!$V:$V,"<>*EXECUTED*"))} -> 0 | I7: =C7*VLOOKUP(C$6,'FX RATES'!$E$1:$F$50,2,FALSE)+D7*VLOOKUP(D$6,'FX RATES'!$E$1:$F$50,2,FALSE)+E7*VLOOKUP(E$6,'FX RATES'!$E$1:$F$50,2,FALSE)+F7*VLOOKUP(F$6,'FX RATES'!$E$1:$F$50,2,FALSE)+G7*VLOOKUP(G$6,'FX RATES'!$E$1:$F$50,2,FALSE)+H7*VLOOKUP(H$6,'FX RATES'!$E$1:$F$50,2,FALSE) -> 3951.8559 | K7: =B7 -> EMLAK | L7: {=SUMIFS(FLOWS!$C:$C,FLOWS!$A:$A,$B$2,FLOWS!$E:$E,$K7,FLOWS!$D:$D,L$6,FLOWS!$H:$H,">="&$C$4,FLOWS!$H:$H,"<="&$U$4)+SUM(SUMIFS(DEALS!$J:$J,DEALS!$A:$A,{"*REFUND*","*EXECUTED*"},DEALS!$G:$G,$B$2,DEALS!$E:$E,">="&$C$4,DEALS!$E:$E,"<="&$U$4,DEALS!$K:$K,L$6,DEALS!$M:$M,$K7,DEALS!$N:$N,"<>*RECEIVED*",DEALS!$N:$N,"<>*EXECUTED*"))+SUM(SUMIFS(DEALS!$R:$R,DEALS!$A:$A,{"*REFUND*","*EXECUTED*"},DEALS!$O:$O,$B$2,DEALS!$E:$E,">="&$C$4,DEALS!$E:$E,"<="&$U$4,DEALS!$S:$S,L$6,DEALS!$U:$U,$K7,DEALS!$V:$V,"<>*RECEIVED*",DEALS!$V:$V,"<>*EXECUTED*"))} -> 0 | M7: {=SUMIFS(FLOWS!$C:$C,FLOWS!$A:$A,$B$2,FLOWS!$E:$E,$K7,FLOWS!$D:$D,M$6,FLOWS!$H:$H,">="&$C$4,FLOWS!$H:$H,"<="&$U$4)+SUM(SUMIFS(DEALS!$J:$J,DEALS!$A:$A,{"*REFUND*","*EXECUTED*"},DEALS!$G:$G,$B$2,DEALS!$E:$E,">="&$C$4,DEALS!$E:$E,"<="&$U$4,DEALS!$K:$K,M$6,DEALS!$M:$M,$K7,DEALS!$N:$N,"<>*RECEIVED*",DEALS!$N:$N,"<>*EXECUTED*"))+SUM(SUMIFS(DEALS!$R:$R,DEALS!$A:$A,{"*REFUND*","*EXECUTED*"},DEALS!$O:$O,$B$2,DEALS!$E:$E,">="&$C$4,DEALS!$E:$E,"<="&$U$4,DEALS!$S:$S,M$6,DEALS!$U:$U,$K7,DEALS!$V:$V,"<>*RECEIVED*",DEALS!$V:$V,"<>*EXECUTED*"))} -> 0 | N7: {=SUMIFS(FLOWS!$C:$C,FLOWS!$A:$A,$B$2,FLOWS!$E:$E,$K7,FLOWS!$D:$D,N$6,FLOWS!$H:$H,">="&$C$4,FLOWS!$H:$H,"<="&$U$4)+SUM(SUMIFS(DEALS!$J:$J,DEALS!$A:$A,{"*REFUND*","*EXECUTED*"},DEALS!$G:$G,$B$2,DEALS!$E:$E,">="&$C$4,DEALS!$E:$E,"<="&$U$4,DEALS!$K:$K,N$6,DEALS!$M:$M,$K7,DEALS!$N:$N,"<>*RECEIVED*",DEALS!$N:$N,"<>*EXECUTED*"))+SUM(SUMIFS(DEALS!$R:$R,DEALS!$A:$A,{"*REFUND*","*EXECUTED*"},DEALS!$O:$O,$B$2,DEALS!$E:$E,">="&$C$4,DEALS!$E:$E,"<="&$U$4,DEALS!$S:$S,N$6,DEALS!$U:$U,$K7,DEALS!$V:$V,"<>*RECEIVED*",DEALS!$V:$V,"<>*EXECUTED*"))} -> 0 | O7: {=SUMIFS(FLOWS!$C:$C,FLOWS!$A:$A,$B$2,FLOWS!$E:$E,$K7,FLOWS!$D:$D,O$6,FLOWS!$H:$H,">="&$C$4,FLOWS!$H:$H,"<="&$U$4)+SUM(SUMIFS(DEALS!$J:$J,DEALS!$A:$A,{"*REFUND*","*EXECUTED*"},DEALS!$G:$G,$B$2,DEALS!$E:$E,">="&$C$4,DEALS!$E:$E,"<="&$U$4,DEALS!$K:$K,O$6,DEALS!$M:$M,$K7,DEALS!$N:$N,"<>*RECEIVED*",DEALS!$N:$N,"<>*EXECUTED*"))+SUM(SUMIFS(DEALS!$R:$R,DEALS!$A:$A,{"*REFUND*","*EXECUTED*"},DEALS!$O:$O,$B$2,DEALS!$E:$E,">="&$C$4,DEALS!$E:$E,"<="&$U$4,DEALS!$S:$S,O$6,DEALS!$U:$U,$K7,DEALS!$V:$V,"<>*RECEIVED*",DEALS!$V:$V,"<>*EXECUTED*"))} -> 0 | P7: {=SUMIFS(FLOWS!$C:$C,FLOWS!$A:$A,$B$2,FLOWS!$E:$E,$K7,FLOWS!$D:$D,P$6,FLOWS!$H:$H,">="&$C$4,FLOWS!$H:$H,"<="&$U$4)+SUM(SUMIFS(DEALS!$J:$J,DEALS!$A:$A,{"*REFUND*","*EXECUTED*"},DEALS!$G:$G,$B$2,DEALS!$E:$E,">="&$C$4,DEALS!$E:$E,"<="&$U$4,DEALS!$K:$K,P$6,DEALS!$M:$M,$K7,DEALS!$N:$N,"<>*RECEIVED*",DEALS!$N:$N,"<>*EXECUTED*"))+SUM(SUMIFS(DEALS!$R:$R,DEALS!$A:$A,{"*REFUND*","*EXECUTED*"},DEALS!$O:$O,$B$2,DEALS!$E:$E,">="&$C$4,DEALS!$E:$E,"<="&$U$4,DEALS!$S:$S,P$6,DEALS!$U:$U,$K7,DEALS!$V:$V,"<>*RECEIVED*",DEALS!$V:$V,"<>*EXECUTED*"))} -> 0 | Q7: {=SUMIFS(FLOWS!$C:$C,FLOWS!$A:$A,$B$2,FLOWS!$E:$E,$K7,FLOWS!$D:$D,Q$6,FLOWS!$H:$H,">="&$C$4,FLOWS!$H:$H,"<="&$U$4)+SUM(SUMIFS(DEALS!$J:$J,DEALS!$A:$A,{"*REFUND*","*EXECUTED*"},DEALS!$G:$G,$B$2,DEALS!$E:$E,">="&$C$4,DEALS!$E:$E,"<="&$U$4,DEALS!$K:$K,Q$6,DEALS!$M:$M,$K7,DEALS!$N:$N,"<>*RECEIVED*",DEALS!$N:$N,"<>*EXECUTED*"))+SUM(SUMIFS(DEALS!$R:$R,DEALS!$A:$A,{"*REFUND*","*EXECUTED*"},DEALS!$O:$O,$B$2,DEALS!$E:$E,">="&$C$4,DEALS!$E:$E,"<="&$U$4,DEALS!$S:$S,Q$6,DEALS!$U:$U,$K7,DEALS!$V:$V,"<>*RECEIVED*",DEALS!$V:$V,"<>*EXECUTED*"))} -> 0 | R7: =L7*VLOOKUP(L$6,'FX RATES'!$E$1:$F$50,2,FALSE)+M7*VLOOKUP(M$6,'FX RATES'!$E$1:$F$50,2,FALSE)+N7*VLOOKUP(N$6,'FX RATES'!$E$1:$F$50,2,FALSE)+O7*VLOOKUP(O$6,'FX RATES'!$E$1:$F$50,2,FALSE)+P7*VLOOKUP(P$6,'FX RATES'!$E$1:$F$50,2,FALSE)+Q7*VLOOKUP(Q$6,'FX RATES'!$E$1:$F$50,2,FALSE) -> 0 | T7: =B7 -> EMLAK | U7: {=SUMIFS(BALANCES!$C:$C,BALANCES!$A:$A,$B$2,BALANCES!$B:$B,$T7,BALANCES!$D:$D,U$6)+SUMIFS(FLOWS!$C:$C,FLOWS!$A:$A,$B$2,FLOWS!$E:$E,$T7,FLOWS!$D:$D,U$6,FLOWS!$H:$H,"<="&$U$4)+SUM(SUMIFS(DEALS!$J:$J,DEALS!$A:$A,{"*REFUND*","*EXECUTED*"},DEALS!$G:$G,$B$2,DEALS!$E:$E,"<="&$U$4,DEALS!$K:$K,U$6,DEALS!$M:$M,$T7,DEALS!$N:$N,"<>*RECEIVED*",DEALS!$N:$N,"<>*EXECUTED*"))+SUM(SUMIFS(DEALS!$R:$R,DEALS!$A:$A,{"*REFUND*","*EXECUTED*"},DEALS!$O:$O,$B$2,DEALS!$E:$E,"<="&$U$4,DEALS!$S:$S,U$6,DEALS!$U:$U,$T7,DEALS!$V:$V,"<>*RECEIVED*",DEALS!$V:$V,"<>*EXECUTED*"))} -> 2197.03 | V7: {=SUMIFS(BALANCES!$C:$C,BALANCES!$A:$A,$B$2,BALANCES!$B:$B,$T7,BALANCES!$D:$D,V$6)+SUMIFS(FLOWS!$C:$C,FLOWS!$A:$A,$B$2,FLOWS!$E:$E,$T7,FLOWS!$D:$D,V$6,FLOWS!$H:$H,"<="&$U$4)+SUM(SUMIFS(DEALS!$J:$J,DEALS!$A:$A,{"*REFUND*","*EXECUTED*"},DEALS!$G:$G,$B$2,DEALS!$E:$E,"<="&$U$4,DEALS!$K:$K,V$6,DEALS!$M:$M,$T7,DEALS!$N:$N,"<>*RECEIVED*",DEALS!$N:$N,"<>*EXECUTED*"))+SUM(SUMIFS(DEALS!$R:$R,DEALS!$A:$A,{"*REFUND*","*EXECUTED*"},DEALS!$O:$O,$B$2,DEALS!$E:$E,"<="&$U$4,DEALS!$S:$S,V$6,DEALS!$U:$U,$T7,DEALS!$V:$V,"<>*RECEIVED*",DEALS!$V:$V,"<>*EXECUTED*"))} -> 44.88 | W7: {=SUMIFS(BALANCES!$C:$C,BALANCES!$A:$A,$B$2,BALANCES!$B:$B,$T7,BALANCES!$D:$D,W$6)+SUMIFS(FLOWS!$C:$C,FLOWS!$A:$A,$B$2,FLOWS!$E:$E,$T7,FLOWS!$D:$D,W$6,FLOWS!$H:$H,"<="&$U$4)+SUM(SUMIFS(DEALS!$J:$J,DEALS!$A:$A,{"*REFUND*","*EXECUTED*"},DEALS!$G:$G,$B$2,DEALS!$E:$E,"<="&$U$4,DEALS!$K:$K,W$6,DEALS!$M:$M,$T7,DEALS!$N:$N,"<>*RECEIVED*",DEALS!$N:$N,"<>*EXECUTED*"))+SUM(SUMIFS(DEALS!$R:$R,DEALS!$A:$A,{"*REFUND*","*EXECUTED*"},DEALS!$O:$O,$B$2,DEALS!$E:$E,"<="&$U$4,DEALS!$S:$S,W$6,DEALS!$U:$U,$T7,DEALS!$V:$V,"<>*RECEIVED*",DEALS!$V:$V,"<>*EXECUTED*"))} -> 54.77 | X7: {=SUMIFS(BALANCES!$C:$C,BALANCES!$A:$A,$B$2,BALANCES!$B:$B,$T7,BALANCES!$D:$D,X$6)+SUMIFS(FLOWS!$C:$C,FLOWS!$A:$A,$B$2,FLOWS!$E:$E,$T7,FLOWS!$D:$D,X$6,FLOWS!$H:$H,"<="&$U$4)+SUM(SUMIFS(DEALS!$J:$J,DEALS!$A:$A,{"*REFUND*","*EXECUTED*"},DEALS!$G:$G,$B$2,DEALS!$E:$E,"<="&$U$4,DEALS!$K:$K,X$6,DEALS!$M:$M,$T7,DEALS!$N:$N,"<>*RECEIVED*",DEALS!$N:$N,"<>*EXECUTED*"))+SUM(SUMIFS(DEALS!$R:$R,DEALS!$A:$A,{"*REFUND*","*EXECUTED*"},DEALS!$O:$O,$B$2,DEALS!$E:$E,"<="&$U$4,DEALS!$S:$S,X$6,DEALS!$U:$U,$T7,DEALS!$V:$V,"<>*RECEIVED*",DEALS!$V:$V,"<>*EXECUTED*"))} -> 6221.49 | Y7: {=SUMIFS(BALANCES!$C:$C,BALANCES!$A:$A,$B$2,BALANCES!$B:$B,$T7,BALANCES!$D:$D,Y$6)+SUMIFS(FLOWS!$C:$C,FLOWS!$A:$A,$B$2,FLOWS!$E:$E,$T7,FLOWS!$D:$D,Y$6,FLOWS!$H:$H,"<="&$U$4)+SUM(SUMIFS(DEALS!$J:$J,DEALS!$A:$A,{"*REFUND*","*EXECUTED*"},DEALS!$G:$G,$B$2,DEALS!$E:$E,"<="&$U$4,DEALS!$K:$K,Y$6,DEALS!$M:$M,$T7,DEALS!$N:$N,"<>*RECEIVED*",DEALS!$N:$N,"<>*EXECUTED*"))+SUM(SUMIFS(DEALS!$R:$R,DEALS!$A:$A,{"*REFUND*","*EXECUTED*"},DEALS!$O:$O,$B$2,DEALS!$E:$E,"<="&$U$4,DEALS!$S:$S,Y$6,DEALS!$U:$U,$T7,DEALS!$V:$V,"<>*RECEIVED*",DEALS!$V:$V,"<>*EXECUTED*"))} -> 0 | Z7: {=SUMIFS(BALANCES!$C:$C,BALANCES!$A:$A,$B$2,BALANCES!$B:$B,$T7,BALANCES!$D:$D,Z$6)+SUMIFS(FLOWS!$C:$C,FLOWS!$A:$A,$B$2,FLOWS!$E:$E,$T7,FLOWS!$D:$D,Z$6,FLOWS!$H:$H,"<="&$U$4)+SUM(SUMIFS(DEALS!$J:$J,DEALS!$A:$A,{"*REFUND*","*EXECUTED*"},DEALS!$G:$G,$B$2,DEALS!$E:$E,"<="&$U$4,DEALS!$K:$K,Z$6,DEALS!$M:$M,$T7,DEALS!$N:$N,"<>*RECEIVED*",DEALS!$N:$N,"<>*EXECUTED*"))+SUM(SUMIFS(DEALS!$R:$R,DEALS!$A:$A,{"*REFUND*","*EXECUTED*"},DEALS!$O:$O,$B$2,DEALS!$E:$E,"<="&$U$4,DEALS!$S:$S,Z$6,DEALS!$U:$U,$T7,DEALS!$V:$V,"<>*RECEIVED*",DEALS!$V:$V,"<>*EXECUTED*"))} -> 0 | AA7: =U7*VLOOKUP(U$6,'FX RATES'!$E$1:$F$50,2,FALSE)+V7*VLOOKUP(V$6,'FX RATES'!$E$1:$F$50,2,FALSE)+W7*VLOOKUP(W$6,'FX RATES'!$E$1:$F$50,2,FALSE)+X7*VLOOKUP(X$6,'FX RATES'!$E$1:$F$50,2,FALSE)+Y7*VLOOKUP(Y$6,'FX RATES'!$E$1:$F$50,2,FALSE)+Z7*VLOOKUP(Z$6,'FX RATES'!$E$1:$F$50,2,FALSE) -> 3951.8559 | AC7: =I7+R7-AA7 -> 0
B8: CBD | C8: {=SUMIFS(BALANCES!$C:$C,BALANCES!$A:$A,$B$2,BALANCES!$B:$B,$B8,BALANCES!$D:$D,C$6)+SUMIFS(FLOWS!$C:$C,FLOWS!$A:$A,$B$2,FLOWS!$E:$E,$B8,FLOWS!$D:$D,C$6,FLOWS!$H:$H,"<"&$C$4)+SUM(SUMIFS(DEALS!$J:$J,DEALS!$A:$A,{"*REFUND*","*EXECUTED*"},DEALS!$G:$G,$B$2,DEALS!$E:$E,"<"&$C$4,DEALS!$K:$K,C$6,DEALS!$M:$M,$B8,DEALS!$N:$N,"<>*RECEIVED*",DEALS!$N:$N,"<>*EXECUTED*"))+SUM(SUMIFS(DEALS!$R:$R,DEALS!$A:$A,{"*REFUND*","*EXECUTED*"},DEALS!$O:$O,$B$2,DEALS!$E:$E,"<"&$C$4,DEALS!$S:$S,C$6,DEALS!$U:$U,$B8,DEALS!$V:$V,"<>*RECEIVED*",DEALS!$V:$V,"<>*EXECUTED*"))} -> 93787.7 | D8: {=SUMIFS(BALANCES!$C:$C,BALANCES!$A:$A,$B$2,BALANCES!$B:$B,$B8,BALANCES!$D:$D,D$6)+SUMIFS(FLOWS!$C:$C,FLOWS!$A:$A,$B$2,FLOWS!$E:$E,$B8,FLOWS!$D:$D,D$6,FLOWS!$H:$H,"<"&$C$4)+SUM(SUMIFS(DEALS!$J:$J,DEALS!$A:$A,{"*REFUND*","*EXECUTED*"},DEALS!$G:$G,$B$2,DEALS!$E:$E,"<"&$C$4,DEALS!$K:$K,D$6,DEALS!$M:$M,$B8,DEALS!$N:$N,"<>*RECEIVED*",DEALS!$N:$N,"<>*EXECUTED*"))+SUM(SUMIFS(DEALS!$R:$R,DEALS!$A:$A,{"*REFUND*","*EXECUTED*"},DEALS!$O:$O,$B$2,DEALS!$E:$E,"<"&$C$4,DEALS!$S:$S,D$6,DEALS!$U:$U,$B8,DEALS!$V:$V,"<>*RECEIVED*",DEALS!$V:$V,"<>*EXECUTED*"))} -> 893.77 | E8: {=SUMIFS(BALANCES!$C:$C,BALANCES!$A:$A,$B$2,BALANCES!$B:$B,$B8,BALANCES!$D:$D,E$6)+SUMIFS(FLOWS!$C:$C,FLOWS!$A:$A,$B$2,FLOWS!$E:$E,$B8,FLOWS!$D:$D,E$6,FLOWS!$H:$H,"<"&$C$4)+SUM(SUMIFS(DEALS!$J:$J,DEALS!$A:$A,{"*REFUND*","*EXECUTED*"},DEALS!$G:$G,$B$2,DEALS!$E:$E,"<"&$C$4,DEALS!$K:$K,E$6,DEALS!$M:$M,$B8,DEALS!$N:$N,"<>*RECEIVED*",DEALS!$N:$N,"<>*EXECUTED*"))+SUM(SUMIFS(DEALS!$R:$R,DEALS!$A:$A,{"*REFUND*","*EXECUTED*"},DEALS!$O:$O,$B$2,DEALS!$E:$E,"<"&$C$4,DEALS!$S:$S,E$6,DEALS!$U:$U,$B8,DEALS!$V:$V,"<>*RECEIVED*",DEALS!$V:$V,"<>*EXECUTED*"))} -> 6100.28 | F8: {=SUMIFS(BALANCES!$C:$C,BALANCES!$A:$A,$B$2,BALANCES!$B:$B,$B8,BALANCES!$D:$D,F$6)+SUMIFS(FLOWS!$C:$C,FLOWS!$A:$A,$B$2,FLOWS!$E:$E,$B8,FLOWS!$D:$D,F$6,FLOWS!$H:$H,"<"&$C$4)+SUM(SUMIFS(DEALS!$J:$J,DEALS!$A:$A,{"*REFUND*","*EXECUTED*"},DEALS!$G:$G,$B$2,DEALS!$E:$E,"<"&$C$4,DEALS!$K:$K,F$6,DEALS!$M:$M,$B8,DEALS!$N:$N,"<>*RECEIVED*",DEALS!$N:$N,"<>*EXECUTED*"))+SUM(SUMIFS(DEALS!$R:$R,DEALS!$A:$A,{"*REFUND*","*EXECUTED*"},DEALS!$O:$O,$B$2,DEALS!$E:$E,"<"&$C$4,DEALS!$S:$S,F$6,DEALS!$U:$U,$B8,DEALS!$V:$V,"<>*RECEIVED*",DEALS!$V:$V,"<>*EXECUTED*"))} -> 1577693.5 | G8: {=SUMIFS(BALANCES!$C:$C,BALANCES!$A:$A,$B$2,BALANCES!$B:$B,$B8,BALANCES!$D:$D,G$6)+SUMIFS(FLOWS!$C:$C,FLOWS!$A:$A,$B$2,FLOWS!$E:$E,$B8,FLOWS!$D:$D,G$6,FLOWS!$H:$H,"<"&$C$4)+SUM(SUMIFS(DEALS!$J:$J,DEALS!$A:$A,{"*REFUND*","*EXECUTED*"},DEALS!$G:$G,$B$2,DEALS!$E:$E,"<"&$C$4,DEALS!$K:$K,G$6,DEALS!$M:$M,$B8,DEALS!$N:$N,"<>*RECEIVED*",DEALS!$N:$N,"<>*EXECUTED*"))+SUM(SUMIFS(DEALS!$R:$R,DEALS!$A:$A,{"*REFUND*","*EXECUTED*"},DEALS!$O:$O,$B$2,DEALS!$E:$E,"<"&$C$4,DEALS!$S:$S,G$6,DEALS!$U:$U,$B8,DEALS!$V:$V,"<>*RECEIVED*",DEALS!$V:$V,"<>*EXECUTED*"))} -> 0 | H8: {=SUMIFS(BALANCES!$C:$C,BALANCES!$A:$A,$B$2,BALANCES!$B:$B,$B8,BALANCES!$D:$D,H$6)+SUMIFS(FLOWS!$C:$C,FLOWS!$A:$A,$B$2,FLOWS!$E:$E,$B8,FLOWS!$D:$D,H$6,FLOWS!$H:$H,"<"&$C$4)+SUM(SUMIFS(DEALS!$J:$J,DEALS!$A:$A,{"*REFUND*","*EXECUTED*"},DEALS!$G:$G,$B$2,DEALS!$E:$E,"<"&$C$4,DEALS!$K:$K,H$6,DEALS!$M:$M,$B8,DEALS!$N:$N,"<>*RECEIVED*",DEALS!$N:$N,"<>*EXECUTED*"))+SUM(SUMIFS(DEALS!$R:$R,DEALS!$A:$A,{"*REFUND*","*EXECUTED*"},DEALS!$O:$O,$B$2,DEALS!$E:$E,"<"&$C$4,DEALS!$S:$S,H$6,DEALS!$U:$U,$B8,DEALS!$V:$V,"<>*RECEIVED*",DEALS!$V:$V,"<>*EXECUTED*"))} -> 0 | I8: =C8*VLOOKUP(C$6,'FX RATES'!$E$1:$F$50,2,FALSE)+D8*VLOOKUP(D$6,'FX RATES'!$E$1:$F$50,2,FALSE)+E8*VLOOKUP(E$6,'FX RATES'!$E$1:$F$50,2,FALSE)+F8*VLOOKUP(F$6,'FX RATES'!$E$1:$F$50,2,FALSE)+G8*VLOOKUP(G$6,'FX RATES'!$E$1:$F$50,2,FALSE)+H8*VLOOKUP(H$6,'FX RATES'!$E$1:$F$50,2,FALSE) -> 525308.54 | K8: =B8 -> CBD | L8: {=SUMIFS(FLOWS!$C:$C,FLOWS!$A:$A,$B$2,FLOWS!$E:$E,$K8,FLOWS!$D:$D,L$6,FLOWS!$H:$H,">="&$C$4,FLOWS!$H:$H,"<="&$U$4)+SUM(SUMIFS(DEALS!$J:$J,DEALS!$A:$A,{"*REFUND*","*EXECUTED*"},DEALS!$G:$G,$B$2,DEALS!$E:$E,">="&$C$4,DEALS!$E:$E,"<="&$U$4,DEALS!$K:$K,L$6,DEALS!$M:$M,$K8,DEALS!$N:$N,"<>*RECEIVED*",DEALS!$N:$N,"<>*EXECUTED*"))+SUM(SUMIFS(DEALS!$R:$R,DEALS!$A:$A,{"*REFUND*","*EXECUTED*"},DEALS!$O:$O,$B$2,DEALS!$E:$E,">="&$C$4,DEALS!$E:$E,"<="&$U$4,DEALS!$S:$S,L$6,DEALS!$U:$U,$K8,DEALS!$V:$V,"<>*RECEIVED*",DEALS!$V:$V,"<>*EXECUTED*"))} -> 3012058.3 | M8: {=SUMIFS(FLOWS!$C:$C,FLOWS!$A:$A,$B$2,FLOWS!$E:$E,$K8,FLOWS!$D:$D,M$6,FLOWS!$H:$H,">="&$C$4,FLOWS!$H:$H,"<="&$U$4)+SUM(SUMIFS(DEALS!$J:$J,DEALS!$A:$A,{"*REFUND*","*EXECUTED*"},DEALS!$G:$G,$B$2,DEALS!$E:$E,">="&$C$4,DEALS!$E:$E,"<="&$U$4,DEALS!$K:$K,M$6,DEALS!$M:$M,$K8,DEALS!$N:$N,"<>*RECEIVED*",DEALS!$N:$N,"<>*EXECUTED*"))+SUM(SUMIFS(DEALS!$R:$R,DEALS!$A:$A,{"*REFUND*","*EXECUTED*"},DEALS!$O:$O,$B$2,DEALS!$E:$E,">="&$C$4,DEALS!$E:$E,"<="&$U$4,DEALS!$S:$S,M$6,DEALS!$U:$U,$K8,DEALS!$V:$V,"<>*RECEIVED*",DEALS!$V:$V,"<>*EXECUTED*"))} -> 0 | N8: {=SUMIFS(FLOWS!$C:$C,FLOWS!$A:$A,$B$2,FLOWS!$E:$E,$K8,FLOWS!$D:$D,N$6,FLOWS!$H:$H,">="&$C$4,FLOWS!$H:$H,"<="&$U$4)+SUM(SUMIFS(DEALS!$J:$J,DEALS!$A:$A,{"*REFUND*","*EXECUTED*"},DEALS!$G:$G,$B$2,DEALS!$E:$E,">="&$C$4,DEALS!$E:$E,"<="&$U$4,DEALS!$K:$K,N$6,DEALS!$M:$M,$K8,DEALS!$N:$N,"<>*RECEIVED*",DEALS!$N:$N,"<>*EXECUTED*"))+SUM(SUMIFS(DEALS!$R:$R,DEALS!$A:$A,{"*REFUND*","*EXECUTED*"},DEALS!$O:$O,$B$2,DEALS!$E:$E,">="&$C$4,DEALS!$E:$E,"<="&$U$4,DEALS!$S:$S,N$6,DEALS!$U:$U,$K8,DEALS!$V:$V,"<>*RECEIVED*",DEALS!$V:$V,"<>*EXECUTED*"))} -> 0 | O8: {=SUMIFS(FLOWS!$C:$C,FLOWS!$A:$A,$B$2,FLOWS!$E:$E,$K8,FLOWS!$D:$D,O$6,FLOWS!$H:$H,">="&$C$4,FLOWS!$H:$H,"<="&$U$4)+SUM(SUMIFS(DEALS!$J:$J,DEALS!$A:$A,{"*REFUND*","*EXECUTED*"},DEALS!$G:$G,$B$2,DEALS!$E:$E,">="&$C$4,DEALS!$E:$E,"<="&$U$4,DEALS!$K:$K,O$6,DEALS!$M:$M,$K8,DEALS!$N:$N,"<>*RECEIVED*",DEALS!$N:$N,"<>*EXECUTED*"))+SUM(SUMIFS(DEALS!$R:$R,DEALS!$A:$A,{"*REFUND*","*EXECUTED*"},DEALS!$O:$O,$B$2,DEALS!$E:$E,">="&$C$4,DEALS!$E:$E,"<="&$U$4,DEALS!$S:$S,O$6,DEALS!$U:$U,$K8,DEALS!$V:$V,"<>*RECEIVED*",DEALS!$V:$V,"<>*EXECUTED*"))} -> 0 | P8: {=SUMIFS(FLOWS!$C:$C,FLOWS!$A:$A,$B$2,FLOWS!$E:$E,$K8,FLOWS!$D:$D,P$6,FLOWS!$H:$H,">="&$C$4,FLOWS!$H:$H,"<="&$U$4)+SUM(SUMIFS(DEALS!$J:$J,DEALS!$A:$A,{"*REFUND*","*EXECUTED*"},DEALS!$G:$G,$B$2,DEALS!$E:$E,">="&$C$4,DEALS!$E:$E,"<="&$U$4,DEALS!$K:$K,P$6,DEALS!$M:$M,$K8,DEALS!$N:$N,"<>*RECEIVED*",DEALS!$N:$N,"<>*EXECUTED*"))+SUM(SUMIFS(DEALS!$R:$R,DEALS!$A:$A,{"*REFUND*","*EXECUTED*"},DEALS!$O:$O,$B$2,DEALS!$E:$E,">="&$C$4,DEALS!$E:$E,"<="&$U$4,DEALS!$S:$S,P$6,DEALS!$U:$U,$K8,DEALS!$V:$V,"<>*RECEIVED*",DEALS!$V:$V,"<>*EXECUTED*"))} -> 0 | Q8: {=SUMIFS(FLOWS!$C:$C,FLOWS!$A:$A,$B$2,FLOWS!$E:$E,$K8,FLOWS!$D:$D,Q$6,FLOWS!$H:$H,">="&$C$4,FLOWS!$H:$H,"<="&$U$4)+SUM(SUMIFS(DEALS!$J:$J,DEALS!$A:$A,{"*REFUND*","*EXECUTED*"},DEALS!$G:$G,$B$2,DEALS!$E:$E,">="&$C$4,DEALS!$E:$E,"<="&$U$4,DEALS!$K:$K,Q$6,DEALS!$M:$M,$K8,DEALS!$N:$N,"<>*RECEIVED*",DEALS!$N:$N,"<>*EXECUTED*"))+SUM(SUMIFS(DEALS!$R:$R,DEALS!$A:$A,{"*REFUND*","*EXECUTED*"},DEALS!$O:$O,$B$2,DEALS!$E:$E,">="&$C$4,DEALS!$E:$E,"<="&$U$4,DEALS!$S:$S,Q$6,DEALS!$U:$U,$K8,DEALS!$V:$V,"<>*RECEIVED*",DEALS!$V:$V,"<>*EXECUTED*"))} -> 0 | R8: =L8*VLOOKUP(L$6,'FX RATES'!$E$1:$F$50,2,FALSE)+M8*VLOOKUP(M$6,'FX RATES'!$E$1:$F$50,2,FALSE)+N8*VLOOKUP(N$6,'FX RATES'!$E$1:$F$50,2,FALSE)+O8*VLOOKUP(O$6,'FX RATES'!$E$1:$F$50,2,FALSE)+P8*VLOOKUP(P$6,'FX RATES'!$E$1:$F$50,2,FALSE)+Q8*VLOOKUP(Q$6,'FX RATES'!$E$1:$F$50,2,FALSE) -> 3012058.3 | T8: =B8 -> CBD | U8: {=SUMIFS(BALANCES!$C:$C,BALANCES!$A:$A,$B$2,BALANCES!$B:$B,$T8,BALANCES!$D:$D,U$6)+SUMIFS(FLOWS!$C:$C,FLOWS!$A:$A,$B$2,FLOWS!$E:$E,$T8,FLOWS!$D:$D,U$6,FLOWS!$H:$H,"<="&$U$4)+SUM(SUMIFS(DEALS!$J:$J,DEALS!$A:$A,{"*REFUND*","*EXECUTED*"},DEALS!$G:$G,$B$2,DEALS!$E:$E,"<="&$U$4,DEALS!$K:$K,U$6,DEALS!$M:$M,$T8,DEALS!$N:$N,"<>*RECEIVED*",DEALS!$N:$N,"<>*EXECUTED*"))+SUM(SUMIFS(DEALS!$R:$R,DEALS!$A:$A,{"*REFUND*","*EXECUTED*"},DEALS!$O:$O,$B$2,DEALS!$E:$E,"<="&$U$4,DEALS!$S:$S,U$6,DEALS!$U:$U,$T8,DEALS!$V:$V,"<>*RECEIVED*",DEALS!$V:$V,"<>*EXECUTED*"))} -> 3105846 | V8: {=SUMIFS(BALANCES!$C:$C,BALANCES!$A:$A,$B$2,BALANCES!$B:$B,$T8,BALANCES!$D:$D,V$6)+SUMIFS(FLOWS!$C:$C,FLOWS!$A:$A,$B$2,FLOWS!$E:$E,$T8,FLOWS!$D:$D,V$6,FLOWS!$H:$H,"<="&$U$4)+SUM(SUMIFS(DEALS!$J:$J,DEALS!$A:$A,{"*REFUND*","*EXECUTED*"},DEALS!$G:$G,$B$2,DEALS!$E:$E,"<="&$U$4,DEALS!$K:$K,V$6,DEALS!$M:$M,$T8,DEALS!$N:$N,"<>*RECEIVED*",DEALS!$N:$N,"<>*EXECUTED*"))+SUM(SUMIFS(DEALS!$R:$R,DEALS!$A:$A,{"*REFUND*","*EXECUTED*"},DEALS!$O:$O,$B$2,DEALS!$E:$E,"<="&$U$4,DEALS!$S:$S,V$6,DEALS!$U:$U,$T8,DEALS!$V:$V,"<>*RECEIVED*",DEALS!$V:$V,"<>*EXECUTED*"))} -> 893.77 | W8: {=SUMIFS(BALANCES!$C:$C,BALANCES!$A:$A,$B$2,BALANCES!$B:$B,$T8,BALANCES!$D:$D,W$6)+SUMIFS(FLOWS!$C:$C,FLOWS!$A:$A,$B$2,FLOWS!$E:$E,$T8,FLOWS!$D:$D,W$6,FLOWS!$H:$H,"<="&$U$4)+SUM(SUMIFS(DEALS!$J:$J,DEALS!$A:$A,{"*REFUND*","*EXECUTED*"},DEALS!$G:$G,$B$2,DEALS!$E:$E,"<="&$U$4,DEALS!$K:$K,W$6,DEALS!$M:$M,$T8,DEALS!$N:$N,"<>*RECEIVED*",DEALS!$N:$N,"<>*EXECUTED*"))+SUM(SUMIFS(DEALS!$R:$R,DEALS!$A:$A,{"*REFUND*","*EXECUTED*"},DEALS!$O:$O,$B$2,DEALS!$E:$E,"<="&$U$4,DEALS!$S:$S,W$6,DEALS!$U:$U,$T8,DEALS!$V:$V,"<>*RECEIVED*",DEALS!$V:$V,"<>*EXECUTED*"))} -> 6100.28 | X8: {=SUMIFS(BALANCES!$C:$C,BALANCES!$A:$A,$B$2,BALANCES!$B:$B,$T8,BALANCES!$D:$D,X$6)+SUMIFS(FLOWS!$C:$C,FLOWS!$A:$A,$B$2,FLOWS!$E:$E,$T8,FLOWS!$D:$D,X$6,FLOWS!$H:$H,"<="&$U$4)+SUM(SUMIFS(DEALS!$J:$J,DEALS!$A:$A,{"*REFUND*","*EXECUTED*"},DEALS!$G:$G,$B$2,DEALS!$E:$E,"<="&$U$4,DEALS!$K:$K,X$6,DEALS!$M:$M,$T8,DEALS!$N:$N,"<>*RECEIVED*",DEALS!$N:$N,"<>*EXECUTED*"))+SUM(SUMIFS(DEALS!$R:$R,DEALS!$A:$A,{"*REFUND*","*EXECUTED*"},DEALS!$O:$O,$B$2,DEALS!$E:$E,"<="&$U$4,DEALS!$S:$S,X$6,DEALS!$U:$U,$T8,DEALS!$V:$V,"<>*RECEIVED*",DEALS!$V:$V,"<>*EXECUTED*"))} -> 1577693.5 | Y8: {=SUMIFS(BALANCES!$C:$C,BALANCES!$A:$A,$B$2,BALANCES!$B:$B,$T8,BALANCES!$D:$D,Y$6)+SUMIFS(FLOWS!$C:$C,FLOWS!$A:$A,$B$2,FLOWS!$E:$E,$T8,FLOWS!$D:$D,Y$6,FLOWS!$H:$H,"<="&$U$4)+SUM(SUMIFS(DEALS!$J:$J,DEALS!$A:$A,{"*REFUND*","*EXECUTED*"},DEALS!$G:$G,$B$2,DEALS!$E:$E,"<="&$U$4,DEALS!$K:$K,Y$6,DEALS!$M:$M,$T8,DEALS!$N:$N,"<>*RECEIVED*",DEALS!$N:$N,"<>*EXECUTED*"))+SUM(SUMIFS(DEALS!$R:$R,DEALS!$A:$A,{"*REFUND*","*EXECUTED*"},DEALS!$O:$O,$B$2,DEALS!$E:$E,"<="&$U$4,DEALS!$S:$S,Y$6,DEALS!$U:$U,$T8,DEALS!$V:$V,"<>*RECEIVED*",DEALS!$V:$V,"<>*EXECUTED*"))} -> 0 | Z8: {=SUMIFS(BALANCES!$C:$C,BALANCES!$A:$A,$B$2,BALANCES!$B:$B,$T8,BALANCES!$D:$D,Z$6)+SUMIFS(FLOWS!$C:$C,FLOWS!$A:$A,$B$2,FLOWS!$E:$E,$T8,FLOWS!$D:$D,Z$6,FLOWS!$H:$H,"<="&$U$4)+SUM(SUMIFS(DEALS!$J:$J,DEALS!$A:$A,{"*REFUND*","*EXECUTED*"},DEALS!$G:$G,$B$2,DEALS!$E:$E,"<="&$U$4,DEALS!$K:$K,Z$6,DEALS!$M:$M,$T8,DEALS!$N:$N,"<>*RECEIVED*",DEALS!$N:$N,"<>*EXECUTED*"))+SUM(SUMIFS(DEALS!$R:$R,DEALS!$A:$A,{"*REFUND*","*EXECUTED*"},DEALS!$O:$O,$B$2,DEALS!$E:$E,"<="&$U$4,DEALS!$S:$S,Z$6,DEALS!$U:$U,$T8,DEALS!$V:$V,"<>*RECEIVED*",DEALS!$V:$V,"<>*EXECUTED*"))} -> 0 | AA8: =U8*VLOOKUP(U$6,'FX RATES'!$E$1:$F$50,2,FALSE)+V8*VLOOKUP(V$6,'FX RATES'!$E$1:$F$50,2,FALSE)+W8*VLOOKUP(W$6,'FX RATES'!$E$1:$F$50,2,FALSE)+X8*VLOOKUP(X$6,'FX RATES'!$E$1:$F$50,2,FALSE)+Y8*VLOOKUP(Y$6,'FX RATES'!$E$1:$F$50,2,FALSE)+Z8*VLOOKUP(Z$6,'FX RATES'!$E$1:$F$50,2,FALSE) -> 3537366.9 | AC8: =I8+R8-AA8 -> 0
B9: MISR | C9: {=SUMIFS(BALANCES!$C:$C,BALANCES!$A:$A,$B$2,BALANCES!$B:$B,$B9,BALANCES!$D:$D,C$6)+SUMIFS(FLOWS!$C:$C,FLOWS!$A:$A,$B$2,FLOWS!$E:$E,$B9,FLOWS!$D:$D,C$6,FLOWS!$H:$H,"<"&$C$4)+SUM(SUMIFS(DEALS!$J:$J,DEALS!$A:$A,{"*REFUND*","*EXECUTED*"},DEALS!$G:$G,$B$2,DEALS!$E:$E,"<"&$C$4,DEALS!$K:$K,C$6,DEALS!$M:$M,$B9,DEALS!$N:$N,"<>*RECEIVED*",DEALS!$N:$N,"<>*EXECUTED*"))+SUM(SUMIFS(DEALS!$R:$R,DEALS!$A:$A,{"*REFUND*","*EXECUTED*"},DEALS!$O:$O,$B$2,DEALS!$E:$E,"<"&$C$4,DEALS!$S:$S,C$6,DEALS!$U:$U,$B9,DEALS!$V:$V,"<>*RECEIVED*",DEALS!$V:$V,"<>*EXECUTED*"))} -> 2916.76 | D9: {=SUMIFS(BALANCES!$C:$C,BALANCES!$A:$A,$B$2,BALANCES!$B:$B,$B9,BALANCES!$D:$D,D$6)+SUMIFS(FLOWS!$C:$C,FLOWS!$A:$A,$B$2,FLOWS!$E:$E,$B9,FLOWS!$D:$D,D$6,FLOWS!$H:$H,"<"&$C$4)+SUM(SUMIFS(DEALS!$J:$J,DEALS!$A:$A,{"*REFUND*","*EXECUTED*"},DEALS!$G:$G,$B$2,DEALS!$E:$E,"<"&$C$4,DEALS!$K:$K,D$6,DEALS!$M:$M,$B9,DEALS!$N:$N,"<>*RECEIVED*",DEALS!$N:$N,"<>*EXECUTED*"))+SUM(SUMIFS(DEALS!$R:$R,DEALS!$A:$A,{"*REFUND*","*EXECUTED*"},DEALS!$O:$O,$B$2,DEALS!$E:$E,"<"&$C$4,DEALS!$S:$S,D$6,DEALS!$U:$U,$B9,DEALS!$V:$V,"<>*RECEIVED*",DEALS!$V:$V,"<>*EXECUTED*"))} -> 712.19 | E9: {=SUMIFS(BALANCES!$C:$C,BALANCES!$A:$A,$B$2,BALANCES!$B:$B,$B9,BALANCES!$D:$D,E$6)+SUMIFS(FLOWS!$C:$C,FLOWS!$A:$A,$B$2,FLOWS!$E:$E,$B9,FLOWS!$D:$D,E$6,FLOWS!$H:$H,"<"&$C$4)+SUM(SUMIFS(DEALS!$J:$J,DEALS!$A:$A,{"*REFUND*","*EXECUTED*"},DEALS!$G:$G,$B$2,DEALS!$E:$E,"<"&$C$4,DEALS!$K:$K,E$6,DEALS!$M:$M,$B9,DEALS!$N:$N,"<>*RECEIVED*",DEALS!$N:$N,"<>*EXECUTED*"))+SUM(SUMIFS(DEALS!$R:$R,DEALS!$A:$A,{"*REFUND*","*EXECUTED*"},DEALS!$O:$O,$B$2,DEALS!$E:$E,"<"&$C$4,DEALS!$S:$S,E$6,DEALS!$U:$U,$B9,DEALS!$V:$V,"<>*RECEIVED*",DEALS!$V:$V,"<>*EXECUTED*"))} -> 0 | F9: {=SUMIFS(BALANCES!$C:$C,BALANCES!$A:$A,$B$2,BALANCES!$B:$B,$B9,BALANCES!$D:$D,F$6)+SUMIFS(FLOWS!$C:$C,FLOWS!$A:$A,$B$2,FLOWS!$E:$E,$B9,FLOWS!$D:$D,F$6,FLOWS!$H:$H,"<"&$C$4)+SUM(SUMIFS(DEALS!$J:$J,DEALS!$A:$A,{"*REFUND*","*EXECUTED*"},DEALS!$G:$G,$B$2,DEALS!$E:$E,"<"&$C$4,DEALS!$K:$K,F$6,DEALS!$M:$M,$B9,DEALS!$N:$N,"<>*RECEIVED*",DEALS!$N:$N,"<>*EXECUTED*"))+SUM(SUMIFS(DEALS!$R:$R,DEALS!$A:$A,{"*REFUND*","*EXECUTED*"},DEALS!$O:$O,$B$2,DEALS!$E:$E,"<"&$C$4,DEALS!$S:$S,F$6,DEALS!$U:$U,$B9,DEALS!$V:$V,"<>*RECEIVED*",DEALS!$V:$V,"<>*EXECUTED*"))} -> 4430.61 | G9: {=SUMIFS(BALANCES!$C:$C,BALANCES!$A:$A,$B$2,BALANCES!$B:$B,$B9,BALANCES!$D:$D,G$6)+SUMIFS(FLOWS!$C:$C,FLOWS!$A:$A,$B$2,FLOWS!$E:$E,$B9,FLOWS!$D:$D,G$6,FLOWS!$H:$H,"<"&$C$4)+SUM(SUMIFS(DEALS!$J:$J,DEALS!$A:$A,{"*REFUND*","*EXECUTED*"},DEALS!$G:$G,$B$2,DEALS!$E:$E,"<"&$C$4,DEALS!$K:$K,G$6,DEALS!$M:$M,$B9,DEALS!$N:$N,"<>*RECEIVED*",DEALS!$N:$N,"<>*EXECUTED*"))+SUM(SUMIFS(DEALS!$R:$R,DEALS!$A:$A,{"*REFUND*","*EXECUTED*"},DEALS!$O:$O,$B$2,DEALS!$E:$E,"<"&$C$4,DEALS!$S:$S,G$6,DEALS!$U:$U,$B9,DEALS!$V:$V,"<>*RECEIVED*",DEALS!$V:$V,"<>*EXECUTED*"))} -> 0 | H9: {=SUMIFS(BALANCES!$C:$C,BALANCES!$A:$A,$B$2,BALANCES!$B:$B,$B9,BALANCES!$D:$D,H$6)+SUMIFS(FLOWS!$C:$C,FLOWS!$A:$A,$B$2,FLOWS!$E:$E,$B9,FLOWS!$D:$D,H$6,FLOWS!$H:$H,"<"&$C$4)+SUM(SUMIFS(DEALS!$J:$J,DEALS!$A:$A,{"*REFUND*","*EXECUTED*"},DEALS!$G:$G,$B$2,DEALS!$E:$E,"<"&$C$4,DEALS!$K:$K,H$6,DEALS!$M:$M,$B9,DEALS!$N:$N,"<>*RECEIVED*",DEALS!$N:$N,"<>*EXECUTED*"))+SUM(SUMIFS(DEALS!$R:$R,DEALS!$A:$A,{"*REFUND*","*EXECUTED*"},DEALS!$O:$O,$B$2,DEALS!$E:$E,"<"&$C$4,DEALS!$S:$S,H$6,DEALS!$U:$U,$B9,DEALS!$V:$V,"<>*RECEIVED*",DEALS!$V:$V,"<>*EXECUTED*"))} -> 0 | I9: =C9*VLOOKUP(C$6,'FX RATES'!$E$1:$F$50,2,FALSE)+D9*VLOOKUP(D$6,'FX RATES'!$E$1:$F$50,2,FALSE)+E9*VLOOKUP(E$6,'FX RATES'!$E$1:$F$50,2,FALSE)+F9*VLOOKUP(F$6,'FX RATES'!$E$1:$F$50,2,FALSE)+G9*VLOOKUP(G$6,'FX RATES'!$E$1:$F$50,2,FALSE)+H9*VLOOKUP(H$6,'FX RATES'!$E$1:$F$50,2,FALSE) -> 4962.1158 | K9: =B9 -> MISR | L9: {=SUMIFS(FLOWS!$C:$C,FLOWS!$A:$A,$B$2,FLOWS!$E:$E,$K9,FLOWS!$D:$D,L$6,FLOWS!$H:$H,">="&$C$4,FLOWS!$H:$H,"<="&$U$4)+SUM(SUMIFS(DEALS!$J:$J,DEALS!$A:$A,{"*REFUND*","*EXECUTED*"},DEALS!$G:$G,$B$2,DEALS!$E:$E,">="&$C$4,DEALS!$E:$E,"<="&$U$4,DEALS!$K:$K,L$6,DEALS!$M:$M,$K9,DEALS!$N:$N,"<>*RECEIVED*",DEALS!$N:$N,"<>*EXECUTED*"))+SUM(SUMIFS(DEALS!$R:$R,DEALS!$A:$A,{"*REFUND*","*EXECUTED*"},DEALS!$O:$O,$B$2,DEALS!$E:$E,">="&$C$4,DEALS!$E:$E,"<="&$U$4,DEALS!$S:$S,L$6,DEALS!$U:$U,$K9,DEALS!$V:$V,"<>*RECEIVED*",DEALS!$V:$V,"<>*EXECUTED*"))} -> 0 | M9: {=SUMIFS(FLOWS!$C:$C,FLOWS!$A:$A,$B$2,FLOWS!$E:$E,$K9,FLOWS!$D:$D,M$6,FLOWS!$H:$H,">="&$C$4,FLOWS!$H:$H,"<="&$U$4)+SUM(SUMIFS(DEALS!$J:$J,DEALS!$A:$A,{"*REFUND*","*EXECUTED*"},DEALS!$G:$G,$B$2,DEALS!$E:$E,">="&$C$4,DEALS!$E:$E,"<="&$U$4,DEALS!$K:$K,M$6,DEALS!$M:$M,$K9,DEALS!$N:$N,"<>*RECEIVED*",DEALS!$N:$N,"<>*EXECUTED*"))+SUM(SUMIFS(DEALS!$R:$R,DEALS!$A:$A,{"*REFUND*","*EXECUTED*"},DEALS!$O:$O,$B$2,DEALS!$E:$E,">="&$C$4,DEALS!$E:$E,"<="&$U$4,DEALS!$S:$S,M$6,DEALS!$U:$U,$K9,DEALS!$V:$V,"<>*RECEIVED*",DEALS!$V:$V,"<>*EXECUTED*"))} -> 0 | N9: {=SUMIFS(FLOWS!$C:$C,FLOWS!$A:$A,$B$2,FLOWS!$E:$E,$K9,FLOWS!$D:$D,N$6,FLOWS!$H:$H,">="&$C$4,FLOWS!$H:$H,"<="&$U$4)+SUM(SUMIFS(DEALS!$J:$J,DEALS!$A:$A,{"*REFUND*","*EXECUTED*"},DEALS!$G:$G,$B$2,DEALS!$E:$E,">="&$C$4,DEALS!$E:$E,"<="&$U$4,DEALS!$K:$K,N$6,DEALS!$M:$M,$K9,DEALS!$N:$N,"<>*RECEIVED*",DEALS!$N:$N,"<>*EXECUTED*"))+SUM(SUMIFS(DEALS!$R:$R,DEALS!$A:$A,{"*REFUND*","*EXECUTED*"},DEALS!$O:$O,$B$2,DEALS!$E:$E,">="&$C$4,DEALS!$E:$E,"<="&$U$4,DEALS!$S:$S,N$6,DEALS!$U:$U,$K9,DEALS!$V:$V,"<>*RECEIVED*",DEALS!$V:$V,"<>*EXECUTED*"))} -> 0 | O9: {=SUMIFS(FLOWS!$C:$C,FLOWS!$A:$A,$B$2,FLOWS!$E:$E,$K9,FLOWS!$D:$D,O$6,FLOWS!$H:$H,">="&$C$4,FLOWS!$H:$H,"<="&$U$4)+SUM(SUMIFS(DEALS!$J:$J,DEALS!$A:$A,{"*REFUND*","*EXECUTED*"},DEALS!$G:$G,$B$2,DEALS!$E:$E,">="&$C$4,DEALS!$E:$E,"<="&$U$4,DEALS!$K:$K,O$6,DEALS!$M:$M,$K9,DEALS!$N:$N,"<>*RECEIVED*",DEALS!$N:$N,"<>*EXECUTED*"))+SUM(SUMIFS(DEALS!$R:$R,DEALS!$A:$A,{"*REFUND*","*EXECUTED*"},DEALS!$O:$O,$B$2,DEALS!$E:$E,">="&$C$4,DEALS!$E:$E,"<="&$U$4,DEALS!$S:$S,O$6,DEALS!$U:$U,$K9,DEALS!$V:$V,"<>*RECEIVED*",DEALS!$V:$V,"<>*EXECUTED*"))} -> 0 | P9: {=SUMIFS(FLOWS!$C:$C,FLOWS!$A:$A,$B$2,FLOWS!$E:$E,$K9,FLOWS!$D:$D,P$6,FLOWS!$H:$H,">="&$C$4,FLOWS!$H:$H,"<="&$U$4)+SUM(SUMIFS(DEALS!$J:$J,DEALS!$A:$A,{"*REFUND*","*EXECUTED*"},DEALS!$G:$G,$B$2,DEALS!$E:$E,">="&$C$4,DEALS!$E:$E,"<="&$U$4,DEALS!$K:$K,P$6,DEALS!$M:$M,$K9,DEALS!$N:$N,"<>*RECEIVED*",DEALS!$N:$N,"<>*EXECUTED*"))+SUM(SUMIFS(DEALS!$R:$R,DEALS!$A:$A,{"*REFUND*","*EXECUTED*"},DEALS!$O:$O,$B$2,DEALS!$E:$E,">="&$C$4,DEALS!$E:$E,"<="&$U$4,DEALS!$S:$S,P$6,DEALS!$U:$U,$K9,DEALS!$V:$V,"<>*RECEIVED*",DEALS!$V:$V,"<>*EXECUTED*"))} -> 0 | Q9: {=SUMIFS(FLOWS!$C:$C,FLOWS!$A:$A,$B$2,FLOWS!$E:$E,$K9,FLOWS!$D:$D,Q$6,FLOWS!$H:$H,">="&$C$4,FLOWS!$H:$H,"<="&$U$4)+SUM(SUMIFS(DEALS!$J:$J,DEALS!$A:$A,{"*REFUND*","*EXECUTED*"},DEALS!$G:$G,$B$2,DEALS!$E:$E,">="&$C$4,DEALS!$E:$E,"<="&$U$4,DEALS!$K:$K,Q$6,DEALS!$M:$M,$K9,DEALS!$N:$N,"<>*RECEIVED*",DEALS!$N:$N,"<>*EXECUTED*"))+SUM(SUMIFS(DEALS!$R:$R,DEALS!$A:$A,{"*REFUND*","*EXECUTED*"},DEALS!$O:$O,$B$2,DEALS!$E:$E,">="&$C$4,DEALS!$E:$E,"<="&$U$4,DEALS!$S:$S,Q$6,DEALS!$U:$U,$K9,DEALS!$V:$V,"<>*RECEIVED*",DEALS!$V:$V,"<>*EXECUTED*"))} -> 0 | R9: =L9*VLOOKUP(L$6,'FX RATES'!$E$1:$F$50,2,FALSE)+M9*VLOOKUP(M$6,'FX RATES'!$E$1:$F$50,2,FALSE)+N9*VLOOKUP(N$6,'FX RATES'!$E$1:$F$50,2,FALSE)+O9*VLOOKUP(O$6,'FX RATES'!$E$1:$F$50,2,FALSE)+P9*VLOOKUP(P$6,'FX RATES'!$E$1:$F$50,2,FALSE)+Q9*VLOOKUP(Q$6,'FX RATES'!$E$1:$F$50,2,FALSE) -> 0 | T9: =B9 -> MISR | U9: {=SUMIFS(BALANCES!$C:$C,BALANCES!$A:$A,$B$2,BALANCES!$B:$B,$T9,BALANCES!$D:$D,U$6)+SUMIFS(FLOWS!$C:$C,FLOWS!$A:$A,$B$2,FLOWS!$E:$E,$T9,FLOWS!$D:$D,U$6,FLOWS!$H:$H,"<="&$U$4)+SUM(SUMIFS(DEALS!$J:$J,DEALS!$A:$A,{"*REFUND*","*EXECUTED*"},DEALS!$G:$G,$B$2,DEALS!$E:$E,"<="&$U$4,DEALS!$K:$K,U$6,DEALS!$M:$M,$T9,DEALS!$N:$N,"<>*RECEIVED*",DEALS!$N:$N,"<>*EXECUTED*"))+SUM(SUMIFS(DEALS!$R:$R,DEALS!$A:$A,{"*REFUND*","*EXECUTED*"},DEALS!$O:$O,$B$2,DEALS!$E:$E,"<="&$U$4,DEALS!$S:$S,U$6,DEALS!$U:$U,$T9,DEALS!$V:$V,"<>*RECEIVED*",DEALS!$V:$V,"<>*EXECUTED*"))} -> 2916.76 | V9: {=SUMIFS(BALANCES!$C:$C,BALANCES!$A:$A,$B$2,BALANCES!$B:$B,$T9,BALANCES!$D:$D,V$6)+SUMIFS(FLOWS!$C:$C,FLOWS!$A:$A,$B$2,FLOWS!$E:$E,$T9,FLOWS!$D:$D,V$6,FLOWS!$H:$H,"<="&$U$4)+SUM(SUMIFS(DEALS!$J:$J,DEALS!$A:$A,{"*REFUND*","*EXECUTED*"},DEALS!$G:$G,$B$2,DEALS!$E:$E,"<="&$U$4,DEALS!$K:$K,V$6,DEALS!$M:$M,$T9,DEALS!$N:$N,"<>*RECEIVED*",DEALS!$N:$N,"<>*EXECUTED*"))+SUM(SUMIFS(DEALS!$R:$R,DEALS!$A:$A,{"*REFUND*","*EXECUTED*"},DEALS!$O:$O,$B$2,DEALS!$E:$E,"<="&$U$4,DEALS!$S:$S,V$6,DEALS!$U:$U,$T9,DEALS!$V:$V,"<>*RECEIVED*",DEALS!$V:$V,"<>*EXECUTED*"))} -> 712.19 | W9: {=SUMIFS(BALANCES!$C:$C,BALANCES!$A:$A,$B$2,BALANCES!$B:$B,$T9,BALANCES!$D:$D,W$6)+SUMIFS(FLOWS!$C:$C,FLOWS!$A:$A,$B$2,FLOWS!$E:$E,$T9,FLOWS!$D:$D,W$6,FLOWS!$H:$H,"<="&$U$4)+SUM(SUMIFS(DEALS!$J:$J,DEALS!$A:$A,{"*REFUND*","*EXECUTED*"},DEALS!$G:$G,$B$2,DEALS!$E:$E,"<="&$U$4,DEALS!$K:$K,W$6,DEALS!$M:$M,$T9,DEALS!$N:$N,"<>*RECEIVED*",DEALS!$N:$N,"<>*EXECUTED*"))+SUM(SUMIFS(DEALS!$R:$R,DEALS!$A:$A,{"*REFUND*","*EXECUTED*"},DEALS!$O:$O,$B$2,DEALS!$E:$E,"<="&$U$4,DEALS!$S:$S,W$6,DEALS!$U:$U,$T9,DEALS!$V:$V,"<>*RECEIVED*",DEALS!$V:$V,"<>*EXECUTED*"))} -> 0 | X9: {=SUMIFS(BALANCES!$C:$C,BALANCES!$A:$A,$B$2,BALANCES!$B:$B,$T9,BALANCES!$D:$D,X$6)+SUMIFS(FLOWS!$C:$C,FLOWS!$A:$A,$B$2,FLOWS!$E:$E,$T9,FLOWS!$D:$D,X$6,FLOWS!$H:$H,"<="&$U$4)+SUM(SUMIFS(DEALS!$J:$J,DEALS!$A:$A,{"*REFUND*","*EXECUTED*"},DEALS!$G:$G,$B$2,DEALS!$E:$E,"<="&$U$4,DEALS!$K:$K,X$6,DEALS!$M:$M,$T9,DEALS!$N:$N,"<>*RECEIVED*",DEALS!$N:$N,"<>*EXECUTED*"))+SUM(SUMIFS(DEALS!$R:$R,DEALS!$A:$A,{"*REFUND*","*EXECUTED*"},DEALS!$O:$O,$B$2,DEALS!$E:$E,"<="&$U$4,DEALS!$S:$S,X$6,DEALS!$U:$U,$T9,DEALS!$V:$V,"<>*RECEIVED*",DEALS!$V:$V,"<>*EXECUTED*"))} -> 4430.61 | Y9: {=SUMIFS(BALANCES!$C:$C,BALANCES!$A:$A,$B$2,BALANCES!$B:$B,$T9,BALANCES!$D:$D,Y$6)+SUMIFS(FLOWS!$C:$C,FLOWS!$A:$A,$B$2,FLOWS!$E:$E,$T9,FLOWS!$D:$D,Y$6,FLOWS!$H:$H,"<="&$U$4)+SUM(SUMIFS(DEALS!$J:$J,DEALS!$A:$A,{"*REFUND*","*EXECUTED*"},DEALS!$G:$G,$B$2,DEALS!$E:$E,"<="&$U$4,DEALS!$K:$K,Y$6,DEALS!$M:$M,$T9,DEALS!$N:$N,"<>*RECEIVED*",DEALS!$N:$N,"<>*EXECUTED*"))+SUM(SUMIFS(DEALS!$R:$R,DEALS!$A:$A,{"*REFUND*","*EXECUTED*"},DEALS!$O:$O,$B$2,DEALS!$E:$E,"<="&$U$4,DEALS!$S:$S,Y$6,DEALS!$U:$U,$T9,DEALS!$V:$V,"<>*RECEIVED*",DEALS!$V:$V,"<>*EXECUTED*"))} -> 0 | Z9: {=SUMIFS(BALANCES!$C:$C,BALANCES!$A:$A,$B$2,BALANCES!$B:$B,$T9,BALANCES!$D:$D,Z$6)+SUMIFS(FLOWS!$C:$C,FLOWS!$A:$A,$B$2,FLOWS!$E:$E,$T9,FLOWS!$D:$D,Z$6,FLOWS!$H:$H,"<="&$U$4)+SUM(SUMIFS(DEALS!$J:$J,DEALS!$A:$A,{"*REFUND*","*EXECUTED*"},DEALS!$G:$G,$B$2,DEALS!$E:$E,"<="&$U$4,DEALS!$K:$K,Z$6,DEALS!$M:$M,$T9,DEALS!$N:$N,"<>*RECEIVED*",DEALS!$N:$N,"<>*EXECUTED*"))+SUM(SUMIFS(DEALS!$R:$R,DEALS!$A:$A,{"*REFUND*","*EXECUTED*"},DEALS!$O:$O,$B$2,DEALS!$E:$E,"<="&$U$4,DEALS!$S:$S,Z$6,DEALS!$U:$U,$T9,DEALS!$V:$V,"<>*RECEIVED*",DEALS!$V:$V,"<>*EXECUTED*"))} -> 0 | AA9: =U9*VLOOKUP(U$6,'FX RATES'!$E$1:$F$50,2,FALSE)+V9*VLOOKUP(V$6,'FX RATES'!$E$1:$F$50,2,FALSE)+W9*VLOOKUP(W$6,'FX RATES'!$E$1:$F$50,2,FALSE)+X9*VLOOKUP(X$6,'FX RATES'!$E$1:$F$50,2,FALSE)+Y9*VLOOKUP(Y$6,'FX RATES'!$E$1:$F$50,2,FALSE)+Z9*VLOOKUP(Z$6,'FX RATES'!$E$1:$F$50,2,FALSE) -> 4962.1158 | AC9: =I9+R9-AA9 -> 0
B10: ADIB | C10: {=SUMIFS(BALANCES!$C:$C,BALANCES!$A:$A,$B$2,BALANCES!$B:$B,$B10,BALANCES!$D:$D,C$6)+SUMIFS(FLOWS!$C:$C,FLOWS!$A:$A,$B$2,FLOWS!$E:$E,$B10,FLOWS!$D:$D,C$6,FLOWS!$H:$H,"<"&$C$4)+SUM(SUMIFS(DEALS!$J:$J,DEALS!$A:$A,{"*REFUND*","*EXECUTED*"},DEALS!$G:$G,$B$2,DEALS!$E:$E,"<"&$C$4,DEALS!$K:$K,C$6,DEALS!$M:$M,$B10,DEALS!$N:$N,"<>*RECEIVED*",DEALS!$N:$N,"<>*EXECUTED*"))+SUM(SUMIFS(DEALS!$R:$R,DEALS!$A:$A,{"*REFUND*","*EXECUTED*"},DEALS!$O:$O,$B$2,DEALS!$E:$E,"<"&$C$4,DEALS!$S:$S,C$6,DEALS!$U:$U,$B10,DEALS!$V:$V,"<>*RECEIVED*",DEALS!$V:$V,"<>*EXECUTED*"))} -> 1080.98 | D10: {=SUMIFS(BALANCES!$C:$C,BALANCES!$A:$A,$B$2,BALANCES!$B:$B,$B10,BALANCES!$D:$D,D$6)+SUMIFS(FLOWS!$C:$C,FLOWS!$A:$A,$B$2,FLOWS!$E:$E,$B10,FLOWS!$D:$D,D$6,FLOWS!$H:$H,"<"&$C$4)+SUM(SUMIFS(DEALS!$J:$J,DEALS!$A:$A,{"*REFUND*","*EXECUTED*"},DEALS!$G:$G,$B$2,DEALS!$E:$E,"<"&$C$4,DEALS!$K:$K,D$6,DEALS!$M:$M,$B10,DEALS!$N:$N,"<>*RECEIVED*",DEALS!$N:$N,"<>*EXECUTED*"))+SUM(SUMIFS(DEALS!$R:$R,DEALS!$A:$A,{"*REFUND*","*EXECUTED*"},DEALS!$O:$O,$B$2,DEALS!$E:$E,"<"&$C$4,DEALS!$S:$S,D$6,DEALS!$U:$U,$B10,DEALS!$V:$V,"<>*RECEIVED*",DEALS!$V:$V,"<>*EXECUTED*"))} -> 0 | E10: {=SUMIFS(BALANCES!$C:$C,BALANCES!$A:$A,$B$2,BALANCES!$B:$B,$B10,BALANCES!$D:$D,E$6)+SUMIFS(FLOWS!$C:$C,FLOWS!$A:$A,$B$2,FLOWS!$E:$E,$B10,FLOWS!$D:$D,E$6,FLOWS!$H:$H,"<"&$C$4)+SUM(SUMIFS(DEALS!$J:$J,DEALS!$A:$A,{"*REFUND*","*EXECUTED*"},DEALS!$G:$G,$B$2,DEALS!$E:$E,"<"&$C$4,DEALS!$K:$K,E$6,DEALS!$M:$M,$B10,DEALS!$N:$N,"<>*RECEIVED*",DEALS!$N:$N,"<>*EXECUTED*"))+SUM(SUMIFS(DEALS!$R:$R,DEALS!$A:$A,{"*REFUND*","*EXECUTED*"},DEALS!$O:$O,$B$2,DEALS!$E:$E,"<"&$C$4,DEALS!$S:$S,E$6,DEALS!$U:$U,$B10,DEALS!$V:$V,"<>*RECEIVED*",DEALS!$V:$V,"<>*EXECUTED*"))} -> 0 | F10: {=SUMIFS(BALANCES!$C:$C,BALANCES!$A:$A,$B$2,BALANCES!$B:$B,$B10,BALANCES!$D:$D,F$6)+SUMIFS(FLOWS!$C:$C,FLOWS!$A:$A,$B$2,FLOWS!$E:$E,$B10,FLOWS!$D:$D,F$6,FLOWS!$H:$H,"<"&$C$4)+SUM(SUMIFS(DEALS!$J:$J,DEALS!$A:$A,{"*REFUND*","*EXECUTED*"},DEALS!$G:$G,$B$2,DEALS!$E:$E,"<"&$C$4,DEALS!$K:$K,F$6,DEALS!$M:$M,$B10,DEALS!$N:$N,"<>*RECEIVED*",DEALS!$N:$N,"<>*EXECUTED*"))+SUM(SUMIFS(DEALS!$R:$R,DEALS!$A:$A,{"*REFUND*","*EXECUTED*"},DEALS!$O:$O,$B$2,DEALS!$E:$E,"<"&$C$4,DEALS!$S:$S,F$6,DEALS!$U:$U,$B10,DEALS!$V:$V,"<>*RECEIVED*",DEALS!$V:$V,"<>*EXECUTED*"))} -> 164092.25 | G10: {=SUMIFS(BALANCES!$C:$C,BALANCES!$A:$A,$B$2,BALANCES!$B:$B,$B10,BALANCES!$D:$D,G$6)+SUMIFS(FLOWS!$C:$C,FLOWS!$A:$A,$B$2,FLOWS!$E:$E,$B10,FLOWS!$D:$D,G$6,FLOWS!$H:$H,"<"&$C$4)+SUM(SUMIFS(DEALS!$J:$J,DEALS!$A:$A,{"*REFUND*","*EXECUTED*"},DEALS!$G:$G,$B$2,DEALS!$E:$E,"<"&$C$4,DEALS!$K:$K,G$6,DEALS!$M:$M,$B10,DEALS!$N:$N,"<>*RECEIVED*",DEALS!$N:$N,"<>*EXECUTED*"))+SUM(SUMIFS(DEALS!$R:$R,DEALS!$A:$A,{"*REFUND*","*EXECUTED*"},DEALS!$O:$O,$B$2,DEALS!$E:$E,"<"&$C$4,DEALS!$S:$S,G$6,DEALS!$U:$U,$B10,DEALS!$V:$V,"<>*RECEIVED*",DEALS!$V:$V,"<>*EXECUTED*"))} -> 0 | H10: {=SUMIFS(BALANCES!$C:$C,BALANCES!$A:$A,$B$2,BALANCES!$B:$B,$B10,BALANCES!$D:$D,H$6)+SUMIFS(FLOWS!$C:$C,FLOWS!$A:$A,$B$2,FLOWS!$E:$E,$B10,FLOWS!$D:$D,H$6,FLOWS!$H:$H,"<"&$C$4)+SUM(SUMIFS(DEALS!$J:$J,DEALS!$A:$A,{"*REFUND*","*EXECUTED*"},DEALS!$G:$G,$B$2,DEALS!$E:$E,"<"&$C$4,DEALS!$K:$K,H$6,DEALS!$M:$M,$B10,DEALS!$N:$N,"<>*RECEIVED*",DEALS!$N:$N,"<>*EXECUTED*"))+SUM(SUMIFS(DEALS!$R:$R,DEALS!$A:$A,{"*REFUND*","*EXECUTED*"},DEALS!$O:$O,$B$2,DEALS!$E:$E,"<"&$C$4,DEALS!$S:$S,H$6,DEALS!$U:$U,$B10,DEALS!$V:$V,"<>*RECEIVED*",DEALS!$V:$V,"<>*EXECUTED*"))} -> 0 | I10: =C10*VLOOKUP(C$6,'FX RATES'!$E$1:$F$50,2,FALSE)+D10*VLOOKUP(D$6,'FX RATES'!$E$1:$F$50,2,FALSE)+E10*VLOOKUP(E$6,'FX RATES'!$E$1:$F$50,2,FALSE)+F10*VLOOKUP(F$6,'FX RATES'!$E$1:$F$50,2,FALSE)+G10*VLOOKUP(G$6,'FX RATES'!$E$1:$F$50,2,FALSE)+H10*VLOOKUP(H$6,'FX RATES'!$E$1:$F$50,2,FALSE) -> 45761.111 | K10: =B10 -> ADIB | L10: {=SUMIFS(FLOWS!$C:$C,FLOWS!$A:$A,$B$2,FLOWS!$E:$E,$K10,FLOWS!$D:$D,L$6,FLOWS!$H:$H,">="&$C$4,FLOWS!$H:$H,"<="&$U$4)+SUM(SUMIFS(DEALS!$J:$J,DEALS!$A:$A,{"*REFUND*","*EXECUTED*"},DEALS!$G:$G,$B$2,DEALS!$E:$E,">="&$C$4,DEALS!$E:$E,"<="&$U$4,DEALS!$K:$K,L$6,DEALS!$M:$M,$K10,DEALS!$N:$N,"<>*RECEIVED*",DEALS!$N:$N,"<>*EXECUTED*"))+SUM(SUMIFS(DEALS!$R:$R,DEALS!$A:$A,{"*REFUND*","*EXECUTED*"},DEALS!$O:$O,$B$2,DEALS!$E:$E,">="&$C$4,DEALS!$E:$E,"<="&$U$4,DEALS!$S:$S,L$6,DEALS!$U:$U,$K10,DEALS!$V:$V,"<>*RECEIVED*",DEALS!$V:$V,"<>*EXECUTED*"))} -> 0 | M10: {=SUMIFS(FLOWS!$C:$C,FLOWS!$A:$A,$B$2,FLOWS!$E:$E,$K10,FLOWS!$D:$D,M$6,FLOWS!$H:$H,">="&$C$4,FLOWS!$H:$H,"<="&$U$4)+SUM(SUMIFS(DEALS!$J:$J,DEALS!$A:$A,{"*REFUND*","*EXECUTED*"},DEALS!$G:$G,$B$2,DEALS!$E:$E,">="&$C$4,DEALS!$E:$E,"<="&$U$4,DEALS!$K:$K,M$6,DEALS!$M:$M,$K10,DEALS!$N:$N,"<>*RECEIVED*",DEALS!$N:$N,"<>*EXECUTED*"))+SUM(SUMIFS(DEALS!$R:$R,DEALS!$A:$A,{"*REFUND*","*EXECUTED*"},DEALS!$O:$O,$B$2,DEALS!$E:$E,">="&$C$4,DEALS!$E:$E,"<="&$U$4,DEALS!$S:$S,M$6,DEALS!$U:$U,$K10,DEALS!$V:$V,"<>*RECEIVED*",DEALS!$V:$V,"<>*EXECUTED*"))} -> 0 | N10: {=SUMIFS(FLOWS!$C:$C,FLOWS!$A:$A,$B$2,FLOWS!$E:$E,$K10,FLOWS!$D:$D,N$6,FLOWS!$H:$H,">="&$C$4,FLOWS!$H:$H,"<="&$U$4)+SUM(SUMIFS(DEALS!$J:$J,DEALS!$A:$A,{"*REFUND*","*EXECUTED*"},DEALS!$G:$G,$B$2,DEALS!$E:$E,">="&$C$4,DEALS!$E:$E,"<="&$U$4,DEALS!$K:$K,N$6,DEALS!$M:$M,$K10,DEALS!$N:$N,"<>*RECEIVED*",DEALS!$N:$N,"<>*EXECUTED*"))+SUM(SUMIFS(DEALS!$R:$R,DEALS!$A:$A,{"*REFUND*","*EXECUTED*"},DEALS!$O:$O,$B$2,DEALS!$E:$E,">="&$C$4,DEALS!$E:$E,"<="&$U$4,DEALS!$S:$S,N$6,DEALS!$U:$U,$K10,DEALS!$V:$V,"<>*RECEIVED*",DEALS!$V:$V,"<>*EXECUTED*"))} -> 0 | O10: {=SUMIFS(FLOWS!$C:$C,FLOWS!$A:$A,$B$2,FLOWS!$E:$E,$K10,FLOWS!$D:$D,O$6,FLOWS!$H:$H,">="&$C$4,FLOWS!$H:$H,"<="&$U$4)+SUM(SUMIFS(DEALS!$J:$J,DEALS!$A:$A,{"*REFUND*","*EXECUTED*"},DEALS!$G:$G,$B$2,DEALS!$E:$E,">="&$C$4,DEALS!$E:$E,"<="&$U$4,DEALS!$K:$K,O$6,DEALS!$M:$M,$K10,DEALS!$N:$N,"<>*RECEIVED*",DEALS!$N:$N,"<>*EXECUTED*"))+SUM(SUMIFS(DEALS!$R:$R,DEALS!$A:$A,{"*REFUND*","*EXECUTED*"},DEALS!$O:$O,$B$2,DEALS!$E:$E,">="&$C$4,DEALS!$E:$E,"<="&$U$4,DEALS!$S:$S,O$6,DEALS!$U:$U,$K10,DEALS!$V:$V,"<>*RECEIVED*",DEALS!$V:$V,"<>*EXECUTED*"))} -> 0 | P10: {=SUMIFS(FLOWS!$C:$C,FLOWS!$A:$A,$B$2,FLOWS!$E:$E,$K10,FLOWS!$D:$D,P$6,FLOWS!$H:$H,">="&$C$4,FLOWS!$H:$H,"<="&$U$4)+SUM(SUMIFS(DEALS!$J:$J,DEALS!$A:$A,{"*REFUND*","*EXECUTED*"},DEALS!$G:$G,$B$2,DEALS!$E:$E,">="&$C$4,DEALS!$E:$E,"<="&$U$4,DEALS!$K:$K,P$6,DEALS!$M:$M,$K10,DEALS!$N:$N,"<>*RECEIVED*",DEALS!$N:$N,"<>*EXECUTED*"))+SUM(SUMIFS(DEALS!$R:$R,DEALS!$A:$A,{"*REFUND*","*EXECUTED*"},DEALS!$O:$O,$B$2,DEALS!$E:$E,">="&$C$4,DEALS!$E:$E,"<="&$U$4,DEALS!$S:$S,P$6,DEALS!$U:$U,$K10,DEALS!$V:$V,"<>*RECEIVED*",DEALS!$V:$V,"<>*EXECUTED*"))} -> 0 | Q10: {=SUMIFS(FLOWS!$C:$C,FLOWS!$A:$A,$B$2,FLOWS!$E:$E,$K10,FLOWS!$D:$D,Q$6,FLOWS!$H:$H,">="&$C$4,FLOWS!$H:$H,"<="&$U$4)+SUM(SUMIFS(DEALS!$J:$J,DEALS!$A:$A,{"*REFUND*","*EXECUTED*"},DEALS!$G:$G,$B$2,DEALS!$E:$E,">="&$C$4,DEALS!$E:$E,"<="&$U$4,DEALS!$K:$K,Q$6,DEALS!$M:$M,$K10,DEALS!$N:$N,"<>*RECEIVED*",DEALS!$N:$N,"<>*EXECUTED*"))+SUM(SUMIFS(DEALS!$R:$R,DEALS!$A:$A,{"*REFUND*","*EXECUTED*"},DEALS!$O:$O,$B$2,DEALS!$E:$E,">="&$C$4,DEALS!$E:$E,"<="&$U$4,DEALS!$S:$S,Q$6,DEALS!$U:$U,$K10,DEALS!$V:$V,"<>*RECEIVED*",DEALS!$V:$V,"<>*EXECUTED*"))} -> 0 | R10: =L10*VLOOKUP(L$6,'FX RATES'!$E$1:$F$50,2,FALSE)+M10*VLOOKUP(M$6,'FX RATES'!$E$1:$F$50,2,FALSE)+N10*VLOOKUP(N$6,'FX RATES'!$E$1:$F$50,2,FALSE)+O10*VLOOKUP(O$6,'FX RATES'!$E$1:$F$50,2,FALSE)+P10*VLOOKUP(P$6,'FX RATES'!$E$1:$F$50,2,FALSE)+Q10*VLOOKUP(Q$6,'FX RATES'!$E$1:$F$50,2,FALSE) -> 0 | T10: =B10 -> ADIB | U10: {=SUMIFS(BALANCES!$C:$C,BALANCES!$A:$A,$B$2,BALANCES!$B:$B,$T10,BALANCES!$D:$D,U$6)+SUMIFS(FLOWS!$C:$C,FLOWS!$A:$A,$B$2,FLOWS!$E:$E,$T10,FLOWS!$D:$D,U$6,FLOWS!$H:$H,"<="&$U$4)+SUM(SUMIFS(DEALS!$J:$J,DEALS!$A:$A,{"*REFUND*","*EXECUTED*"},DEALS!$G:$G,$B$2,DEALS!$E:$E,"<="&$U$4,DEALS!$K:$K,U$6,DEALS!$M:$M,$T10,DEALS!$N:$N,"<>*RECEIVED*",DEALS!$N:$N,"<>*EXECUTED*"))+SUM(SUMIFS(DEALS!$R:$R,DEALS!$A:$A,{"*REFUND*","*EXECUTED*"},DEALS!$O:$O,$B$2,DEALS!$E:$E,"<="&$U$4,DEALS!$S:$S,U$6,DEALS!$U:$U,$T10,DEALS!$V:$V,"<>*RECEIVED*",DEALS!$V:$V,"<>*EXECUTED*"))} -> 1080.98 | V10: {=SUMIFS(BALANCES!$C:$C,BALANCES!$A:$A,$B$2,BALANCES!$B:$B,$T10,BALANCES!$D:$D,V$6)+SUMIFS(FLOWS!$C:$C,FLOWS!$A:$A,$B$2,FLOWS!$E:$E,$T10,FLOWS!$D:$D,V$6,FLOWS!$H:$H,"<="&$U$4)+SUM(SUMIFS(DEALS!$J:$J,DEALS!$A:$A,{"*REFUND*","*EXECUTED*"},DEALS!$G:$G,$B$2,DEALS!$E:$E,"<="&$U$4,DEALS!$K:$K,V$6,DEALS!$M:$M,$T10,DEALS!$N:$N,"<>*RECEIVED*",DEALS!$N:$N,"<>*EXECUTED*"))+SUM(SUMIFS(DEALS!$R:$R,DEALS!$A:$A,{"*REFUND*","*EXECUTED*"},DEALS!$O:$O,$B$2,DEALS!$E:$E,"<="&$U$4,DEALS!$S:$S,V$6,DEALS!$U:$U,$T10,DEALS!$V:$V,"<>*RECEIVED*",DEALS!$V:$V,"<>*EXECUTED*"))} -> 0 | W10: {=SUMIFS(BALANCES!$C:$C,BALANCES!$A:$A,$B$2,BALANCES!$B:$B,$T10,BALANCES!$D:$D,W$6)+SUMIFS(FLOWS!$C:$C,FLOWS!$A:$A,$B$2,FLOWS!$E:$E,$T10,FLOWS!$D:$D,W$6,FLOWS!$H:$H,"<="&$U$4)+SUM(SUMIFS(DEALS!$J:$J,DEALS!$A:$A,{"*REFUND*","*EXECUTED*"},DEALS!$G:$G,$B$2,DEALS!$E:$E,"<="&$U$4,DEALS!$K:$K,W$6,DEALS!$M:$M,$T10,DEALS!$N:$N,"<>*RECEIVED*",DEALS!$N:$N,"<>*EXECUTED*"))+SUM(SUMIFS(DEALS!$R:$R,DEALS!$A:$A,{"*REFUND*","*EXECUTED*"},DEALS!$O:$O,$B$2,DEALS!$E:$E,"<="&$U$4,DEALS!$S:$S,W$6,DEALS!$U:$U,$T10,DEALS!$V:$V,"<>*RECEIVED*",DEALS!$V:$V,"<>*EXECUTED*"))} -> 0 | X10: {=SUMIFS(BALANCES!$C:$C,BALANCES!$A:$A,$B$2,BALANCES!$B:$B,$T10,BALANCES!$D:$D,X$6)+SUMIFS(FLOWS!$C:$C,FLOWS!$A:$A,$B$2,FLOWS!$E:$E,$T10,FLOWS!$D:$D,X$6,FLOWS!$H:$H,"<="&$U$4)+SUM(SUMIFS(DEALS!$J:$J,DEALS!$A:$A,{"*REFUND*","*EXECUTED*"},DEALS!$G:$G,$B$2,DEALS!$E:$E,"<="&$U$4,DEALS!$K:$K,X$6,DEALS!$M:$M,$T10,DEALS!$N:$N,"<>*RECEIVED*",DEALS!$N:$N,"<>*EXECUTED*"))+SUM(SUMIFS(DEALS!$R:$R,DEALS!$A:$A,{"*REFUND*","*EXECUTED*"},DEALS!$O:$O,$B$2,DEALS!$E:$E,"<="&$U$4,DEALS!$S:$S,X$6,DEALS!$U:$U,$T10,DEALS!$V:$V,"<>*RECEIVED*",DEALS!$V:$V,"<>*EXECUTED*"))} -> 164092.25 | Y10: {=SUMIFS(BALANCES!$C:$C,BALANCES!$A:$A,$B$2,BALANCES!$B:$B,$T10,BALANCES!$D:$D,Y$6)+SUMIFS(FLOWS!$C:$C,FLOWS!$A:$A,$B$2,FLOWS!$E:$E,$T10,FLOWS!$D:$D,Y$6,FLOWS!$H:$H,"<="&$U$4)+SUM(SUMIFS(DEALS!$J:$J,DEALS!$A:$A,{"*REFUND*","*EXECUTED*"},DEALS!$G:$G,$B$2,DEALS!$E:$E,"<="&$U$4,DEALS!$K:$K,Y$6,DEALS!$M:$M,$T10,DEALS!$N:$N,"<>*RECEIVED*",DEALS!$N:$N,"<>*EXECUTED*"))+SUM(SUMIFS(DEALS!$R:$R,DEALS!$A:$A,{"*REFUND*","*EXECUTED*"},DEALS!$O:$O,$B$2,DEALS!$E:$E,"<="&$U$4,DEALS!$S:$S,Y$6,DEALS!$U:$U,$T10,DEALS!$V:$V,"<>*RECEIVED*",DEALS!$V:$V,"<>*EXECUTED*"))} -> 0 | Z10: {=SUMIFS(BALANCES!$C:$C,BALANCES!$A:$A,$B$2,BALANCES!$B:$B,$T10,BALANCES!$D:$D,Z$6)+SUMIFS(FLOWS!$C:$C,FLOWS!$A:$A,$B$2,FLOWS!$E:$E,$T10,FLOWS!$D:$D,Z$6,FLOWS!$H:$H,"<="&$U$4)+SUM(SUMIFS(DEALS!$J:$J,DEALS!$A:$A,{"*REFUND*","*EXECUTED*"},DEALS!$G:$G,$B$2,DEALS!$E:$E,"<="&$U$4,DEALS!$K:$K,Z$6,DEALS!$M:$M,$T10,DEALS!$N:$N,"<>*RECEIVED*",DEALS!$N:$N,"<>*EXECUTED*"))+SUM(SUMIFS(DEALS!$R:$R,DEALS!$A:$A,{"*REFUND*","*EXECUTED*"},DEALS!$O:$O,$B$2,DEALS!$E:$E,"<="&$U$4,DEALS!$S:$S,Z$6,DEALS!$U:$U,$T10,DEALS!$V:$V,"<>*RECEIVED*",DEALS!$V:$V,"<>*EXECUTED*"))} -> 0 | AA10: =U10*VLOOKUP(U$6,'FX RATES'!$E$1:$F$50,2,FALSE)+V10*VLOOKUP(V$6,'FX RATES'!$E$1:$F$50,2,FALSE)+W10*VLOOKUP(W$6,'FX RATES'!$E$1:$F$50,2,FALSE)+X10*VLOOKUP(X$6,'FX RATES'!$E$1:$F$50,2,FALSE)+Y10*VLOOKUP(Y$6,'FX RATES'!$E$1:$F$50,2,FALSE)+Z10*VLOOKUP(Z$6,'FX RATES'!$E$1:$F$50,2,FALSE) -> 45761.111 | AC10: =I10+R10-AA10 -> 0
B11: UBL | C11: {=SUMIFS(BALANCES!$C:$C,BALANCES!$A:$A,$B$2,BALANCES!$B:$B,$B11,BALANCES!$D:$D,C$6)+SUMIFS(FLOWS!$C:$C,FLOWS!$A:$A,$B$2,FLOWS!$E:$E,$B11,FLOWS!$D:$D,C$6,FLOWS!$H:$H,"<"&$C$4)+SUM(SUMIFS(DEALS!$J:$J,DEALS!$A:$A,{"*REFUND*","*EXECUTED*"},DEALS!$G:$G,$B$2,DEALS!$E:$E,"<"&$C$4,DEALS!$K:$K,C$6,DEALS!$M:$M,$B11,DEALS!$N:$N,"<>*RECEIVED*",DEALS!$N:$N,"<>*EXECUTED*"))+SUM(SUMIFS(DEALS!$R:$R,DEALS!$A:$A,{"*REFUND*","*EXECUTED*"},DEALS!$O:$O,$B$2,DEALS!$E:$E,"<"&$C$4,DEALS!$S:$S,C$6,DEALS!$U:$U,$B11,DEALS!$V:$V,"<>*RECEIVED*",DEALS!$V:$V,"<>*EXECUTED*"))} -> 12811.26 | D11: {=SUMIFS(BALANCES!$C:$C,BALANCES!$A:$A,$B$2,BALANCES!$B:$B,$B11,BALANCES!$D:$D,D$6)+SUMIFS(FLOWS!$C:$C,FLOWS!$A:$A,$B$2,FLOWS!$E:$E,$B11,FLOWS!$D:$D,D$6,FLOWS!$H:$H,"<"&$C$4)+SUM(SUMIFS(DEALS!$J:$J,DEALS!$A:$A,{"*REFUND*","*EXECUTED*"},DEALS!$G:$G,$B$2,DEALS!$E:$E,"<"&$C$4,DEALS!$K:$K,D$6,DEALS!$M:$M,$B11,DEALS!$N:$N,"<>*RECEIVED*",DEALS!$N:$N,"<>*EXECUTED*"))+SUM(SUMIFS(DEALS!$R:$R,DEALS!$A:$A,{"*REFUND*","*EXECUTED*"},DEALS!$O:$O,$B$2,DEALS!$E:$E,"<"&$C$4,DEALS!$S:$S,D$6,DEALS!$U:$U,$B11,DEALS!$V:$V,"<>*RECEIVED*",DEALS!$V:$V,"<>*EXECUTED*"))} -> 2901.34 | E11: {=SUMIFS(BALANCES!$C:$C,BALANCES!$A:$A,$B$2,BALANCES!$B:$B,$B11,BALANCES!$D:$D,E$6)+SUMIFS(FLOWS!$C:$C,FLOWS!$A:$A,$B$2,FLOWS!$E:$E,$B11,FLOWS!$D:$D,E$6,FLOWS!$H:$H,"<"&$C$4)+SUM(SUMIFS(DEALS!$J:$J,DEALS!$A:$A,{"*REFUND*","*EXECUTED*"},DEALS!$G:$G,$B$2,DEALS!$E:$E,"<"&$C$4,DEALS!$K:$K,E$6,DEALS!$M:$M,$B11,DEALS!$N:$N,"<>*RECEIVED*",DEALS!$N:$N,"<>*EXECUTED*"))+SUM(SUMIFS(DEALS!$R:$R,DEALS!$A:$A,{"*REFUND*","*EXECUTED*"},DEALS!$O:$O,$B$2,DEALS!$E:$E,"<"&$C$4,DEALS!$S:$S,E$6,DEALS!$U:$U,$B11,DEALS!$V:$V,"<>*RECEIVED*",DEALS!$V:$V,"<>*EXECUTED*"))} -> 0 | F11: {=SUMIFS(BALANCES!$C:$C,BALANCES!$A:$A,$B$2,BALANCES!$B:$B,$B11,BALANCES!$D:$D,F$6)+SUMIFS(FLOWS!$C:$C,FLOWS!$A:$A,$B$2,FLOWS!$E:$E,$B11,FLOWS!$D:$D,F$6,FLOWS!$H:$H,"<"&$C$4)+SUM(SUMIFS(DEALS!$J:$J,DEALS!$A:$A,{"*REFUND*","*EXECUTED*"},DEALS!$G:$G,$B$2,DEALS!$E:$E,"<"&$C$4,DEALS!$K:$K,F$6,DEALS!$M:$M,$B11,DEALS!$N:$N,"<>*RECEIVED*",DEALS!$N:$N,"<>*EXECUTED*"))+SUM(SUMIFS(DEALS!$R:$R,DEALS!$A:$A,{"*REFUND*","*EXECUTED*"},DEALS!$O:$O,$B$2,DEALS!$E:$E,"<"&$C$4,DEALS!$S:$S,F$6,DEALS!$U:$U,$B11,DEALS!$V:$V,"<>*RECEIVED*",DEALS!$V:$V,"<>*EXECUTED*"))} -> -2827656.5 | G11: {=SUMIFS(BALANCES!$C:$C,BALANCES!$A:$A,$B$2,BALANCES!$B:$B,$B11,BALANCES!$D:$D,G$6)+SUMIFS(FLOWS!$C:$C,FLOWS!$A:$A,$B$2,FLOWS!$E:$E,$B11,FLOWS!$D:$D,G$6,FLOWS!$H:$H,"<"&$C$4)+SUM(SUMIFS(DEALS!$J:$J,DEALS!$A:$A,{"*REFUND*","*EXECUTED*"},DEALS!$G:$G,$B$2,DEALS!$E:$E,"<"&$C$4,DEALS!$K:$K,G$6,DEALS!$M:$M,$B11,DEALS!$N:$N,"<>*RECEIVED*",DEALS!$N:$N,"<>*EXECUTED*"))+SUM(SUMIFS(DEALS!$R:$R,DEALS!$A:$A,{"*REFUND*","*EXECUTED*"},DEALS!$O:$O,$B$2,DEALS!$E:$E,"<"&$C$4,DEALS!$S:$S,G$6,DEALS!$U:$U,$B11,DEALS!$V:$V,"<>*RECEIVED*",DEALS!$V:$V,"<>*EXECUTED*"))} -> 0 | H11: {=SUMIFS(BALANCES!$C:$C,BALANCES!$A:$A,$B$2,BALANCES!$B:$B,$B11,BALANCES!$D:$D,H$6)+SUMIFS(FLOWS!$C:$C,FLOWS!$A:$A,$B$2,FLOWS!$E:$E,$B11,FLOWS!$D:$D,H$6,FLOWS!$H:$H,"<"&$C$4)+SUM(SUMIFS(DEALS!$J:$J,DEALS!$A:$A,{"*REFUND*","*EXECUTED*"},DEALS!$G:$G,$B$2,DEALS!$E:$E,"<"&$C$4,DEALS!$K:$K,H$6,DEALS!$M:$M,$B11,DEALS!$N:$N,"<>*RECEIVED*",DEALS!$N:$N,"<>*EXECUTED*"))+SUM(SUMIFS(DEALS!$R:$R,DEALS!$A:$A,{"*REFUND*","*EXECUTED*"},DEALS!$O:$O,$B$2,DEALS!$E:$E,"<"&$C$4,DEALS!$S:$S,H$6,DEALS!$U:$U,$B11,DEALS!$V:$V,"<>*RECEIVED*",DEALS!$V:$V,"<>*EXECUTED*"))} -> 0 | I11: =C11*VLOOKUP(C$6,'FX RATES'!$E$1:$F$50,2,FALSE)+D11*VLOOKUP(D$6,'FX RATES'!$E$1:$F$50,2,FALSE)+E11*VLOOKUP(E$6,'FX RATES'!$E$1:$F$50,2,FALSE)+F11*VLOOKUP(F$6,'FX RATES'!$E$1:$F$50,2,FALSE)+G11*VLOOKUP(G$6,'FX RATES'!$E$1:$F$50,2,FALSE)+H11*VLOOKUP(H$6,'FX RATES'!$E$1:$F$50,2,FALSE) -> -753704.12 | K11: =B11 -> UBL | L11: {=SUMIFS(FLOWS!$C:$C,FLOWS!$A:$A,$B$2,FLOWS!$E:$E,$K11,FLOWS!$D:$D,L$6,FLOWS!$H:$H,">="&$C$4,FLOWS!$H:$H,"<="&$U$4)+SUM(SUMIFS(DEALS!$J:$J,DEALS!$A:$A,{"*REFUND*","*EXECUTED*"},DEALS!$G:$G,$B$2,DEALS!$E:$E,">="&$C$4,DEALS!$E:$E,"<="&$U$4,DEALS!$K:$K,L$6,DEALS!$M:$M,$K11,DEALS!$N:$N,"<>*RECEIVED*",DEALS!$N:$N,"<>*EXECUTED*"))+SUM(SUMIFS(DEALS!$R:$R,DEALS!$A:$A,{"*REFUND*","*EXECUTED*"},DEALS!$O:$O,$B$2,DEALS!$E:$E,">="&$C$4,DEALS!$E:$E,"<="&$U$4,DEALS!$S:$S,L$6,DEALS!$U:$U,$K11,DEALS!$V:$V,"<>*RECEIVED*",DEALS!$V:$V,"<>*EXECUTED*"))} -> 0 | M11: {=SUMIFS(FLOWS!$C:$C,FLOWS!$A:$A,$B$2,FLOWS!$E:$E,$K11,FLOWS!$D:$D,M$6,FLOWS!$H:$H,">="&$C$4,FLOWS!$H:$H,"<="&$U$4)+SUM(SUMIFS(DEALS!$J:$J,DEALS!$A:$A,{"*REFUND*","*EXECUTED*"},DEALS!$G:$G,$B$2,DEALS!$E:$E,">="&$C$4,DEALS!$E:$E,"<="&$U$4,DEALS!$K:$K,M$6,DEALS!$M:$M,$K11,DEALS!$N:$N,"<>*RECEIVED*",DEALS!$N:$N,"<>*EXECUTED*"))+SUM(SUMIFS(DEALS!$R:$R,DEALS!$A:$A,{"*REFUND*","*EXECUTED*"},DEALS!$O:$O,$B$2,DEALS!$E:$E,">="&$C$4,DEALS!$E:$E,"<="&$U$4,DEALS!$S:$S,M$6,DEALS!$U:$U,$K11,DEALS!$V:$V,"<>*RECEIVED*",DEALS!$V:$V,"<>*EXECUTED*"))} -> 0 | N11: {=SUMIFS(FLOWS!$C:$C,FLOWS!$A:$A,$B$2,FLOWS!$E:$E,$K11,FLOWS!$D:$D,N$6,FLOWS!$H:$H,">="&$C$4,FLOWS!$H:$H,"<="&$U$4)+SUM(SUMIFS(DEALS!$J:$J,DEALS!$A:$A,{"*REFUND*","*EXECUTED*"},DEALS!$G:$G,$B$2,DEALS!$E:$E,">="&$C$4,DEALS!$E:$E,"<="&$U$4,DEALS!$K:$K,N$6,DEALS!$M:$M,$K11,DEALS!$N:$N,"<>*RECEIVED*",DEALS!$N:$N,"<>*EXECUTED*"))+SUM(SUMIFS(DEALS!$R:$R,DEALS!$A:$A,{"*REFUND*","*EXECUTED*"},DEALS!$O:$O,$B$2,DEALS!$E:$E,">="&$C$4,DEALS!$E:$E,"<="&$U$4,DEALS!$S:$S,N$6,DEALS!$U:$U,$K11,DEALS!$V:$V,"<>*RECEIVED*",DEALS!$V:$V,"<>*EXECUTED*"))} -> 0 | O11: {=SUMIFS(FLOWS!$C:$C,FLOWS!$A:$A,$B$2,FLOWS!$E:$E,$K11,FLOWS!$D:$D,O$6,FLOWS!$H:$H,">="&$C$4,FLOWS!$H:$H,"<="&$U$4)+SUM(SUMIFS(DEALS!$J:$J,DEALS!$A:$A,{"*REFUND*","*EXECUTED*"},DEALS!$G:$G,$B$2,DEALS!$E:$E,">="&$C$4,DEALS!$E:$E,"<="&$U$4,DEALS!$K:$K,O$6,DEALS!$M:$M,$K11,DEALS!$N:$N,"<>*RECEIVED*",DEALS!$N:$N,"<>*EXECUTED*"))+SUM(SUMIFS(DEALS!$R:$R,DEALS!$A:$A,{"*REFUND*","*EXECUTED*"},DEALS!$O:$O,$B$2,DEALS!$E:$E,">="&$C$4,DEALS!$E:$E,"<="&$U$4,DEALS!$S:$S,O$6,DEALS!$U:$U,$K11,DEALS!$V:$V,"<>*RECEIVED*",DEALS!$V:$V,"<>*EXECUTED*"))} -> 0 | P11: {=SUMIFS(FLOWS!$C:$C,FLOWS!$A:$A,$B$2,FLOWS!$E:$E,$K11,FLOWS!$D:$D,P$6,FLOWS!$H:$H,">="&$C$4,FLOWS!$H:$H,"<="&$U$4)+SUM(SUMIFS(DEALS!$J:$J,DEALS!$A:$A,{"*REFUND*","*EXECUTED*"},DEALS!$G:$G,$B$2,DEALS!$E:$E,">="&$C$4,DEALS!$E:$E,"<="&$U$4,DEALS!$K:$K,P$6,DEALS!$M:$M,$K11,DEALS!$N:$N,"<>*RECEIVED*",DEALS!$N:$N,"<>*EXECUTED*"))+SUM(SUMIFS(DEALS!$R:$R,DEALS!$A:$A,{"*REFUND*","*EXECUTED*"},DEALS!$O:$O,$B$2,DEALS!$E:$E,">="&$C$4,DEALS!$E:$E,"<="&$U$4,DEALS!$S:$S,P$6,DEALS!$U:$U,$K11,DEALS!$V:$V,"<>*RECEIVED*",DEALS!$V:$V,"<>*EXECUTED*"))} -> 0 | Q11: {=SUMIFS(FLOWS!$C:$C,FLOWS!$A:$A,$B$2,FLOWS!$E:$E,$K11,FLOWS!$D:$D,Q$6,FLOWS!$H:$H,">="&$C$4,FLOWS!$H:$H,"<="&$U$4)+SUM(SUMIFS(DEALS!$J:$J,DEALS!$A:$A,{"*REFUND*","*EXECUTED*"},DEALS!$G:$G,$B$2,DEALS!$E:$E,">="&$C$4,DEALS!$E:$E,"<="&$U$4,DEALS!$K:$K,Q$6,DEALS!$M:$M,$K11,DEALS!$N:$N,"<>*RECEIVED*",DEALS!$N:$N,"<>*EXECUTED*"))+SUM(SUMIFS(DEALS!$R:$R,DEALS!$A:$A,{"*REFUND*","*EXECUTED*"},DEALS!$O:$O,$B$2,DEALS!$E:$E,">="&$C$4,DEALS!$E:$E,"<="&$U$4,DEALS!$S:$S,Q$6,DEALS!$U:$U,$K11,DEALS!$V:$V,"<>*RECEIVED*",DEALS!$V:$V,"<>*EXECUTED*"))} -> 0 | R11: =L11*VLOOKUP(L$6,'FX RATES'!$E$1:$F$50,2,FALSE)+M11*VLOOKUP(M$6,'FX RATES'!$E$1:$F$50,2,FALSE)+N11*VLOOKUP(N$6,'FX RATES'!$E$1:$F$50,2,FALSE)+O11*VLOOKUP(O$6,'FX RATES'!$E$1:$F$50,2,FALSE)+P11*VLOOKUP(P$6,'FX RATES'!$E$1:$F$50,2,FALSE)+Q11*VLOOKUP(Q$6,'FX RATES'!$E$1:$F$50,2,FALSE) -> 0 | T11: =B11 -> UBL | U11: {=SUMIFS(BALANCES!$C:$C,BALANCES!$A:$A,$B$2,BALANCES!$B:$B,$T11,BALANCES!$D:$D,U$6)+SUMIFS(FLOWS!$C:$C,FLOWS!$A:$A,$B$2,FLOWS!$E:$E,$T11,FLOWS!$D:$D,U$6,FLOWS!$H:$H,"<="&$U$4)+SUM(SUMIFS(DEALS!$J:$J,DEALS!$A:$A,{"*REFUND*","*EXECUTED*"},DEALS!$G:$G,$B$2,DEALS!$E:$E,"<="&$U$4,DEALS!$K:$K,U$6,DEALS!$M:$M,$T11,DEALS!$N:$N,"<>*RECEIVED*",DEALS!$N:$N,"<>*EXECUTED*"))+SUM(SUMIFS(DEALS!$R:$R,DEALS!$A:$A,{"*REFUND*","*EXECUTED*"},DEALS!$O:$O,$B$2,DEALS!$E:$E,"<="&$U$4,DEALS!$S:$S,U$6,DEALS!$U:$U,$T11,DEALS!$V:$V,"<>*RECEIVED*",DEALS!$V:$V,"<>*EXECUTED*"))} -> 12811.26 | V11: {=SUMIFS(BALANCES!$C:$C,BALANCES!$A:$A,$B$2,BALANCES!$B:$B,$T11,BALANCES!$D:$D,V$6)+SUMIFS(FLOWS!$C:$C,FLOWS!$A:$A,$B$2,FLOWS!$E:$E,$T11,FLOWS!$D:$D,V$6,FLOWS!$H:$H,"<="&$U$4)+SUM(SUMIFS(DEALS!$J:$J,DEALS!$A:$A,{"*REFUND*","*EXECUTED*"},DEALS!$G:$G,$B$2,DEALS!$E:$E,"<="&$U$4,DEALS!$K:$K,V$6,DEALS!$M:$M,$T11,DEALS!$N:$N,"<>*RECEIVED*",DEALS!$N:$N,"<>*EXECUTED*"))+SUM(SUMIFS(DEALS!$R:$R,DEALS!$A:$A,{"*REFUND*","*EXECUTED*"},DEALS!$O:$O,$B$2,DEALS!$E:$E,"<="&$U$4,DEALS!$S:$S,V$6,DEALS!$U:$U,$T11,DEALS!$V:$V,"<>*RECEIVED*",DEALS!$V:$V,"<>*EXECUTED*"))} -> 2901.34 | W11: {=SUMIFS(BALANCES!$C:$C,BALANCES!$A:$A,$B$2,BALANCES!$B:$B,$T11,BALANCES!$D:$D,W$6)+SUMIFS(FLOWS!$C:$C,FLOWS!$A:$A,$B$2,FLOWS!$E:$E,$T11,FLOWS!$D:$D,W$6,FLOWS!$H:$H,"<="&$U$4)+SUM(SUMIFS(DEALS!$J:$J,DEALS!$A:$A,{"*REFUND*","*EXECUTED*"},DEALS!$G:$G,$B$2,DEALS!$E:$E,"<="&$U$4,DEALS!$K:$K,W$6,DEALS!$M:$M,$T11,DEALS!$N:$N,"<>*RECEIVED*",DEALS!$N:$N,"<>*EXECUTED*"))+SUM(SUMIFS(DEALS!$R:$R,DEALS!$A:$A,{"*REFUND*","*EXECUTED*"},DEALS!$O:$O,$B$2,DEALS!$E:$E,"<="&$U$4,DEALS!$S:$S,W$6,DEALS!$U:$U,$T11,DEALS!$V:$V,"<>*RECEIVED*",DEALS!$V:$V,"<>*EXECUTED*"))} -> 0 | X11: {=SUMIFS(BALANCES!$C:$C,BALANCES!$A:$A,$B$2,BALANCES!$B:$B,$T11,BALANCES!$D:$D,X$6)+SUMIFS(FLOWS!$C:$C,FLOWS!$A:$A,$B$2,FLOWS!$E:$E,$T11,FLOWS!$D:$D,X$6,FLOWS!$H:$H,"<="&$U$4)+SUM(SUMIFS(DEALS!$J:$J,DEALS!$A:$A,{"*REFUND*","*EXECUTED*"},DEALS!$G:$G,$B$2,DEALS!$E:$E,"<="&$U$4,DEALS!$K:$K,X$6,DEALS!$M:$M,$T11,DEALS!$N:$N,"<>*RECEIVED*",DEALS!$N:$N,"<>*EXECUTED*"))+SUM(SUMIFS(DEALS!$R:$R,DEALS!$A:$A,{"*REFUND*","*EXECUTED*"},DEALS!$O:$O,$B$2,DEALS!$E:$E,"<="&$U$4,DEALS!$S:$S,X$6,DEALS!$U:$U,$T11,DEALS!$V:$V,"<>*RECEIVED*",DEALS!$V:$V,"<>*EXECUTED*"))} -> -2827656.5 | Y11: {=SUMIFS(BALANCES!$C:$C,BALANCES!$A:$A,$B$2,BALANCES!$B:$B,$T11,BALANCES!$D:$D,Y$6)+SUMIFS(FLOWS!$C:$C,FLOWS!$A:$A,$B$2,FLOWS!$E:$E,$T11,FLOWS!$D:$D,Y$6,FLOWS!$H:$H,"<="&$U$4)+SUM(SUMIFS(DEALS!$J:$J,DEALS!$A:$A,{"*REFUND*","*EXECUTED*"},DEALS!$G:$G,$B$2,DEALS!$E:$E,"<="&$U$4,DEALS!$K:$K,Y$6,DEALS!$M:$M,$T11,DEALS!$N:$N,"<>*RECEIVED*",DEALS!$N:$N,"<>*EXECUTED*"))+SUM(SUMIFS(DEALS!$R:$R,DEALS!$A:$A,{"*REFUND*","*EXECUTED*"},DEALS!$O:$O,$B$2,DEALS!$E:$E,"<="&$U$4,DEALS!$S:$S,Y$6,DEALS!$U:$U,$T11,DEALS!$V:$V,"<>*RECEIVED*",DEALS!$V:$V,"<>*EXECUTED*"))} -> 0 | Z11: {=SUMIFS(BALANCES!$C:$C,BALANCES!$A:$A,$B$2,BALANCES!$B:$B,$T11,BALANCES!$D:$D,Z$6)+SUMIFS(FLOWS!$C:$C,FLOWS!$A:$A,$B$2,FLOWS!$E:$E,$T11,FLOWS!$D:$D,Z$6,FLOWS!$H:$H,"<="&$U$4)+SUM(SUMIFS(DEALS!$J:$J,DEALS!$A:$A,{"*REFUND*","*EXECUTED*"},DEALS!$G:$G,$B$2,DEALS!$E:$E,"<="&$U$4,DEALS!$K:$K,Z$6,DEALS!$M:$M,$T11,DEALS!$N:$N,"<>*RECEIVED*",DEALS!$N:$N,"<>*EXECUTED*"))+SUM(SUMIFS(DEALS!$R:$R,DEALS!$A:$A,{"*REFUND*","*EXECUTED*"},DEALS!$O:$O,$B$2,DEALS!$E:$E,"<="&$U$4,DEALS!$S:$S,Z$6,DEALS!$U:$U,$T11,DEALS!$V:$V,"<>*RECEIVED*",DEALS!$V:$V,"<>*EXECUTED*"))} -> 0 | AA11: =U11*VLOOKUP(U$6,'FX RATES'!$E$1:$F$50,2,FALSE)+V11*VLOOKUP(V$6,'FX RATES'!$E$1:$F$50,2,FALSE)+W11*VLOOKUP(W$6,'FX RATES'!$E$1:$F$50,2,FALSE)+X11*VLOOKUP(X$6,'FX RATES'!$E$1:$F$50,2,FALSE)+Y11*VLOOKUP(Y$6,'FX RATES'!$E$1:$F$50,2,FALSE)+Z11*VLOOKUP(Z$6,'FX RATES'!$E$1:$F$50,2,FALSE) -> -753704.12 | AC11: =I11+R11-AA11 -> 0
